Workbook

Sheet READ ME
A2: READ ME — 1 MINUTE
A3: The ONLY tab you use is MATCHDAY. (Bets = engine audit · Dashboard = scoreboard · Method = settings & rules · Model vs Market = context.)
A5: YELLOW CELLS = YOU TYPE. There are only 5 things, all on the Matchday tab:
A6: 1. Odds 1 / X / 2 — the three DECIMAL prices from your betting app (1 = home, X = draw, 2 = away). 21/50 → 1.42 · 7/2 → 4.50 · 15/2 → 8.50. Bet365: Settings → Odds format → Decimal.
A7: 2. Team news OK? — Y or N. Only needed when DECISION says BET.
A8: 3. Placed? + Backed (H/D/A) + Odds you got + Stake you placed — your log AFTER you bet. "Backed" = the outcome on your slip; P&L grades against it, so model updates can never rewrite your record.
A9: 4. Result — H, D, A or Void, after full time.
A10: 5. Closing odds (optional) — the price just before kickoff, for the CLV homework.
A12: EVERYTHING ELSE IS AUTOMATIC: PICK, DECISION, ENGINE STAKE, WHY, FINAL ACTION, STATUS, CLV, the whole Dashboard and your bankroll.
A14: HOW TO READ THE ANSWER
A15: · ENGINE STAKE "–" + FINAL ACTION "❌ NO BET" → the engine DID respond: do not bet this match. Example: South Korea v Czechia at 2.70 / 3.10 / 2.80 → EV +1.6%, below the 2.5% bar → NO BET. Nothing is broken.
A16: · FINAL ACTION "🟢 PLACE £x on [pick]" → bet exactly that amount on exactly that pick, after the team-news check.
... A32: v2.2 — last-mile hardening: pause can no longer distort the STATUS text for un-snapshotted bets; First-time setup now retro-snapshots any bet placed before the script existed; snapshot cells stay writable for shared editors (share view-only with friends regardless — they scale stakes via "£ / £100 bank").

Sheet Dashboard
A1: WC26 GROUP STAGE — VALUE BETTING DASHBOARD
A2: Model snapshot 2026-06-10 14:10 UTC · type odds on the MATCHDAY tab on game day · stakes auto-size from current bankroll
A4: Current bankroll | B4: =Method!B10 -> 1058.3 | C4: Matches today | D4: =COUNTIF(Bets!B2:B73,TODAY()) -> 4 | E4: Engine bets placed | F4: =SUMPRODUCT(--(Bets!AN2:AN73="Y"),--(Bets!AZ2:AZ73="BET")) -> 5 | G4: =IF(F5=0,"","⚠ "&F5&" fun bet(s) logged — excluded from engine quality. Judge the engine on Engine P&L and ✓ rows only.") -> ⚠ 4 fun bet(s) logged — excluded from engine quality. Judge the engine on Engine P&L and ✓ rows only.
A5: Staked (placed) | B5: =SUMIF(Bets!AN2:AN73,"Y",Bets!AP2:AP73) -> 140 | C5: Next match day | D5: =IFERROR(SMALL(Bets!B2:B73,COUNTIF(Bets!B2:B73,"<"&TODAY())+1),"finished") -> 46189 | E5: Fun bets placed | F5: =SUMPRODUCT(--(Bets!AN2:AN73="Y"),--(Bets!AZ2:AZ73<>"BET")) -> 4
A6: Settled P&L | B6: =SUM(Bets!AR2:AR73) -> 58.3 | C6: BET signals live | D6: =COUNTIF(Bets!AH2:AH73,"BET") -> 8 | E6: Avg CLV (logged) | F6: =IFERROR(AVERAGE(Matchday!U4:U75),"–") -> 0.86505467
A7: ROI (settled) | B7: =IF(SUMPRODUCT(--(Bets!AN2:AN73="Y"),--(Bets!AQ2:AQ73<>""),Bets!AP2:AP73)=0,"–",B6/SUMPRODUCT(--(Bets!AN2:AN73="Y"),--(Bets!AQ2:AQ73<>""),Bets!AP2:AP73)) -> 0.41642857 | C7: PASS | D7: =COUNTIF(Bets!AH2:AH73,"PASS") -> 14 | E7: Engine P&L | F7: =SUMIF(Bets!AZ2:AZ73,"BET",Bets!AR2:AR73) -> 48.9
A8: Record W–L | B8: =COUNTIF(Bets!AR2:AR73,">0")&" – "&COUNTIF(Bets!AR2:AR73,"<0") -> 5 – 3 | C8: Awaiting odds | D8: =COUNTIF(Bets!AH2:AH73,"· enter odds") -> 50 | E8: Fun-bet P&L | F8: =SUMIFS(Bets!AR2:AR73,Bets!AN2:AN73,"Y",Bets!AZ2:AZ73,"<>BET") -> 9.4
A9: Open bets | B9: =SUMPRODUCT(--(Bets!AN2:AN73="Y"),--(Bets!AQ2:AQ73="")) -> 1 | C9: Sum of BET stakes | D9: =SUM(Bets!AJ2:AJ73) -> 0
A11: LIVE VALUE BOARD — top BET signals right now (fills as you enter odds)
A12: # | B12: Date | C12: Group | D12: Match | E12: Pick | F12: Odds | G12: EV | H12: Edge | I12: Stake £
A13: {=IFERROR(INDEX(Bets!$A$2:$A$73,MATCH(LARGE(Bets!$AM$2:$AM$73,1),Bets!$AM$2:$AM$73,0)),"")} -> 9 | B13: {=IFERROR(INDEX(Bets!$B$2:$B$73,MATCH(LARGE(Bets!$AM$2:$AM$73,1),Bets!$AM$2:$AM$73,0)),"")} -> 46187 | C13: {=IFERROR(INDEX(Bets!$C$2:$C$73,MATCH(LARGE(Bets!$AM$2:$AM$73,1),Bets!$AM$2:$AM$73,0)),"")} -> E | D13: {=IFERROR(INDEX(Bets!$D$2:$D$73,MATCH(LARGE(Bets!$AM$2:$AM$73,1),Bets!$AM$2:$AM$73,0))&" v "&INDEX(Bets!$E$2:$E$73,MATCH(LARGE(Bets!$AM$2:$AM$73,1),Bets!$AM$2:$AM$73,0)),"")} -> Germany v Curacao | E13: {=IFERROR(INDEX(Bets!$AD$2:$AD$73,MATCH(LARGE(Bets!$AM$2:$AM$73,1),Bets!$AM$2:$AM$73,0)),"")} -> X Draw | F13: {=IFERROR(INDEX(Bets!$AE$2:$AE$73,MATCH(LARGE(Bets!$AM$2:$AM$73,1),Bets!$AM$2:$AM$73,0)),"")} -> 19 | G13: {=IFERROR(INDEX(Bets!$AF$2:$AF$73,MATCH(LARGE(Bets!$AM$2:$AM$73,1),Bets!$AM$2:$AM$73,0)),"")} -> 0.66307727 | H13: {=IFERROR(INDEX(Bets!$AG$2:$AG$73,MATCH(LARGE(Bets!$AM$2:$AM$73,1),Bets!$AM$2:$AM$73,0)),"")} -> 0.049597147 | I13: {=IFERROR(INDEX(Bets!$AJ$2:$AJ$73,MATCH(LARGE(Bets!$AM$2:$AM$73,1),Bets!$AM$2:$AM$73,0)),"")} -> 0
A14: {=IFERROR(INDEX(Bets!$A$2:$A$73,MATCH(LARGE(Bets!$AM$2:$AM$73,2),Bets!$AM$2:$AM$73,0)),"")} -> 13 | B14: {=IFERROR(INDEX(Bets!$B$2:$B$73,MATCH(LARGE(Bets!$AM$2:$AM$73,2),Bets!$AM$2:$AM$73,0)),"")} -> 46188 | C14: {=IFERROR(INDEX(Bets!$C$2:$C$73,MATCH(LARGE(Bets!$AM$2:$AM$73,2),Bets!$AM$2:$AM$73,0)),"")} -> H | D14: {=IFERROR(INDEX(Bets!$D$2:$D$73,MATCH(LARGE(Bets!$AM$2:$AM$73,2),Bets!$AM$2:$AM$73,0))&" v "&INDEX(Bets!$E$2:$E$73,MATCH(LARGE(Bets!$AM$2:$AM$73,2),Bets!$AM$2:$AM$73,0)),"")} -> Spain v Cape Verde | E14: {=IFERROR(INDEX(Bets!$AD$2:$AD$73,MATCH(LARGE(Bets!$AM$2:$AM$73,2),Bets!$AM$2:$AM$73,0)),"")} -> X Draw | F14: {=IFERROR(INDEX(Bets!$AE$2:$AE$73,MATCH(LARGE(Bets!$AM$2:$AM$73,2),Bets!$AM$2:$AM$73,0)),"")} -> 14 | G14: {=IFERROR(INDEX(Bets!$AF$2:$AF$73,MATCH(LARGE(Bets!$AM$2:$AM$73,2),Bets!$AM$2:$AM$73,0)),"")} -> 0.40171 | H14: {=IFERROR(INDEX(Bets!$AG$2:$AG$73,MATCH(LARGE(Bets!$AM$2:$AM$73,2),Bets!$AM$2:$AM$73,0)),"")} -> 0.035180648 | I14: {=IFERROR(INDEX(Bets!$AJ$2:$AJ$73,MATCH(LARGE(Bets!$AM$2:$AM$73,2),Bets!$AM$2:$AM$73,0)),"")} -> 0
A15: {=IFERROR(INDEX(Bets!$A$2:$A$73,MATCH(LARGE(Bets!$AM$2:$AM$73,3),Bets!$AM$2:$AM$73,0)),"")} -> 8 | B15: {=IFERROR(INDEX(Bets!$B$2:$B$73,MATCH(LARGE(Bets!$AM$2:$AM$73,3),Bets!$AM$2:$AM$73,0)),"")} -> 46186 | C15: {=IFERROR(INDEX(Bets!$C$2:$C$73,MATCH(LARGE(Bets!$AM$2:$AM$73,3),Bets!$AM$2:$AM$73,0)),"")} -> D | D15: {=IFERROR(INDEX(Bets!$D$2:$D$73,MATCH(LARGE(Bets!$AM$2:$AM$73,3),Bets!$AM$2:$AM$73,0))&" v "&INDEX(Bets!$E$2:$E$73,MATCH(LARGE(Bets!$AM$2:$AM$73,3),Bets!$AM$2:$AM$73,0)),"")} -> Australia v Turkey | E15: {=IFERROR(INDEX(Bets!$AD$2:$AD$73,MATCH(LARGE(Bets!$AM$2:$AM$73,3),Bets!$AM$2:$AM$73,0)),"")} -> 1 Australia | F15: {=IFERROR(INDEX(Bets!$AE$2:$AE$73,MATCH(LARGE(Bets!$AM$2:$AM$73,3),Bets!$AM$2:$AM$73,0)),"")} -> 5.25 | G15: {=IFERROR(INDEX(Bets!$AF$2:$AF$73,MATCH(LARGE(Bets!$AM$2:$AM$73,3),Bets!$AM$2:$AM$73,0)),"")} -> 0.25800572 | H15: {=IFERROR(INDEX(Bets!$AG$2:$AG$73,MATCH(LARGE(Bets!$AM$2:$AM$73,3),Bets!$AM$2:$AM$73,0)),"")} -> 0.065570164 | I15: {=IFERROR(INDEX(Bets!$AJ$2:$AJ$73,MATCH(LARGE(Bets!$AM$2:$AM$73,3),Bets!$AM$2:$AM$73,0)),"")} -> 0
A16: {=IFERROR(INDEX(Bets!$A$2:$A$73,MATCH(LARGE(Bets!$AM$2:$AM$73,4),Bets!$AM$2:$AM$73,0)),"")} -> 5 | B16: {=IFERROR(INDEX(Bets!$B$2:$B$73,MATCH(LARGE(Bets!$AM$2:$AM$73,4),Bets!$AM$2:$AM$73,0)),"")} -> 46186 | C16: {=IFERROR(INDEX(Bets!$C$2:$C$73,MATCH(LARGE(Bets!$AM$2:$AM$73,4),Bets!$AM$2:$AM$73,0)),"")} -> B | D16: {=IFERROR(INDEX(Bets!$D$2:$D$73,MATCH(LARGE(Bets!$AM$2:$AM$73,4),Bets!$AM$2:$AM$73,0))&" v "&INDEX(Bets!$E$2:$E$73,MATCH(LARGE(Bets!$AM$2:$AM$73,4),Bets!$AM$2:$AM$73,0)),"")} -> Qatar v Switzerland | E16: {=IFERROR(INDEX(Bets!$AD$2:$AD$73,MATCH(LARGE(Bets!$AM$2:$AM$73,4),Bets!$AM$2:$AM$73,0)),"")} -> X Draw | F16: {=IFERROR(INDEX(Bets!$AE$2:$AE$73,MATCH(LARGE(Bets!$AM$2:$AM$73,4),Bets!$AM$2:$AM$73,0)),"")} -> 7.5 | G16: {=IFERROR(INDEX(Bets!$AF$2:$AF$73,MATCH(LARGE(Bets!$AM$2:$AM$73,4),Bets!$AM$2:$AM$73,0)),"")} -> 0.11654745 | H16: {=IFERROR(INDEX(Bets!$AG$2:$AG$73,MATCH(LARGE(Bets!$AM$2:$AM$73,4),Bets!$AM$2:$AM$73,0)),"")} -> 0.026396158 | I16: {=IFERROR(INDEX(Bets!$AJ$2:$AJ$73,MATCH(LARGE(Bets!$AM$2:$AM$73,4),Bets!$AM$2:$AM$73,0)),"")} -> 0
A17: {=IFERROR(INDEX(Bets!$A$2:$A$73,MATCH(LARGE(Bets!$AM$2:$AM$73,5),Bets!$AM$2:$AM$73,0)),"")} -> 6 | B17: {=IFERROR(INDEX(Bets!$B$2:$B$73,MATCH(LARGE(Bets!$AM$2:$AM$73,5),Bets!$AM$2:$AM$73,0)),"")} -> 46186 | C17: {=IFERROR(INDEX(Bets!$C$2:$C$73,MATCH(LARGE(Bets!$AM$2:$AM$73,5),Bets!$AM$2:$AM$73,0)),"")} -> C | D17: {=IFERROR(INDEX(Bets!$D$2:$D$73,MATCH(LARGE(Bets!$AM$2:$AM$73,5),Bets!$AM$2:$AM$73,0))&" v "&INDEX(Bets!$E$2:$E$73,MATCH(LARGE(Bets!$AM$2:$AM$73,5),Bets!$AM$2:$AM$73,0)),"")} -> Brazil v Morocco | E17: {=IFERROR(INDEX(Bets!$AD$2:$AD$73,MATCH(LARGE(Bets!$AM$2:$AM$73,5),Bets!$AM$2:$AM$73,0)),"")} -> 2 Morocco | F17: {=IFERROR(INDEX(Bets!$AE$2:$AE$73,MATCH(LARGE(Bets!$AM$2:$AM$73,5),Bets!$AM$2:$AM$73,0)),"")} -> 5.5 | G17: {=IFERROR(INDEX(Bets!$AF$2:$AF$73,MATCH(LARGE(Bets!$AM$2:$AM$73,5),Bets!$AM$2:$AM$73,0)),"")} -> 0.10709084 | H17: {=IFERROR(INDEX(Bets!$AG$2:$AG$73,MATCH(LARGE(Bets!$AM$2:$AM$73,5),Bets!$AM$2:$AM$73,0)),"")} -> 0.030207955 | I17: {=IFERROR(INDEX(Bets!$AJ$2:$AJ$73,MATCH(LARGE(Bets!$AM$2:$AM$73,5),Bets!$AM$2:$AM$73,0)),"")} -> 0
A18: {=IFERROR(INDEX(Bets!$A$2:$A$73,MATCH(LARGE(Bets!$AM$2:$AM$73,6),Bets!$AM$2:$AM$73,0)),"")} -> 3 | B18: {=IFERROR(INDEX(Bets!$B$2:$B$73,MATCH(LARGE(Bets!$AM$2:$AM$73,6),Bets!$AM$2:$AM$73,0)),"")} -> 46185 | C18: {=IFERROR(INDEX(Bets!$C$2:$C$73,MATCH(LARGE(Bets!$AM$2:$AM$73,6),Bets!$AM$2:$AM$73,0)),"")} -> B | D18: {=IFERROR(INDEX(Bets!$D$2:$D$73,MATCH(LARGE(Bets!$AM$2:$AM$73,6),Bets!$AM$2:$AM$73,0))&" v "&INDEX(Bets!$E$2:$E$73,MATCH(LARGE(Bets!$AM$2:$AM$73,6),Bets!$AM$2:$AM$73,0)),"")} -> Canada v Bosnia and Herzegovina | E18: {=IFERROR(INDEX(Bets!$AD$2:$AD$73,MATCH(LARGE(Bets!$AM$2:$AM$73,6),Bets!$AM$2:$AM$73,0)),"")} -> 1 Canada | F18: {=IFERROR(INDEX(Bets!$AE$2:$AE$73,MATCH(LARGE(Bets!$AM$2:$AM$73,6),Bets!$AM$2:$AM$73,0)),"")} -> 1.85 | G18: {=IFERROR(INDEX(Bets!$AF$2:$AF$73,MATCH(LARGE(Bets!$AM$2:$AM$73,6),Bets!$AM$2:$AM$73,0)),"")} -> 0.079476281 | H18: {=IFERROR(INDEX(Bets!$AG$2:$AG$73,MATCH(LARGE(Bets!$AM$2:$AM$73,6),Bets!$AM$2:$AM$73,0)),"")} -> 0.061387805 | I18: {=IFERROR(INDEX(Bets!$AJ$2:$AJ$73,MATCH(LARGE(Bets!$AM$2:$AM$73,6),Bets!$AM$2:$AM$73,0)),"")} -> 0
A19: {=IFERROR(INDEX(Bets!$A$2:$A$73,MATCH(LARGE(Bets!$AM$2:$AM$73,7),Bets!$AM$2:$AM$73,0)),"")} -> 12 | B19: {=IFERROR(INDEX(Bets!$B$2:$B$73,MATCH(LARGE(Bets!$AM$2:$AM$73,7),Bets!$AM$2:$AM$73,0)),"")} -> 46187 | C19: {=IFERROR(INDEX(Bets!$C$2:$C$73,MATCH(LARGE(Bets!$AM$2:$AM$73,7),Bets!$AM$2:$AM$73,0)),"")} -> F | D19: {=IFERROR(INDEX(Bets!$D$2:$D$73,MATCH(LARGE(Bets!$AM$2:$AM$73,7),Bets!$AM$2:$AM$73,0))&" v "&INDEX(Bets!$E$2:$E$73,MATCH(LARGE(Bets!$AM$2:$AM$73,7),Bets!$AM$2:$AM$73,0)),"")} -> Sweden v Tunisia | E19: {=IFERROR(INDEX(Bets!$AD$2:$AD$73,MATCH(LARGE(Bets!$AM$2:$AM$73,7),Bets!$AM$2:$AM$73,0)),"")} -> 2 Tunisia | F19: {=IFERROR(INDEX(Bets!$AE$2:$AE$73,MATCH(LARGE(Bets!$AM$2:$AM$73,7),Bets!$AM$2:$AM$73,0)),"")} -> 4.33 | G19: {=IFERROR(INDEX(Bets!$AF$2:$AF$73,MATCH(LARGE(Bets!$AM$2:$AM$73,7),Bets!$AM$2:$AM$73,0)),"")} -> 0.054579994 | H19: {=IFERROR(INDEX(Bets!$AG$2:$AG$73,MATCH(LARGE(Bets!$AM$2:$AM$73,7),Bets!$AM$2:$AM$73,0)),"")} -> 0.028208356 | I19: {=IFERROR(INDEX(Bets!$AJ$2:$AJ$73,MATCH(LARGE(Bets!$AM$2:$AM$73,7),Bets!$AM$2:$AM$73,0)),"")} -> 0
A20: {=IFERROR(INDEX(Bets!$A$2:$A$73,MATCH(LARGE(Bets!$AM$2:$AM$73,8),Bets!$AM$2:$AM$73,0)),"")} -> 2 | B20: {=IFERROR(INDEX(Bets!$B$2:$B$73,MATCH(LARGE(Bets!$AM$2:$AM$73,8),Bets!$AM$2:$AM$73,0)),"")} -> 46184 | C20: {=IFERROR(INDEX(Bets!$C$2:$C$73,MATCH(LARGE(Bets!$AM$2:$AM$73,8),Bets!$AM$2:$AM$73,0)),"")} -> A | D20: {=IFERROR(INDEX(Bets!$D$2:$D$73,MATCH(LARGE(Bets!$AM$2:$AM$73,8),Bets!$AM$2:$AM$73,0))&" v "&INDEX(Bets!$E$2:$E$73,MATCH(LARGE(Bets!$AM$2:$AM$73,8),Bets!$AM$2:$AM$73,0)),"")} -> South Korea v Czechia | E20: {=IFERROR(INDEX(Bets!$AD$2:$AD$73,MATCH(LARGE(Bets!$AM$2:$AM$73,8),Bets!$AM$2:$AM$73,0)),"")} -> 1 South Korea | F20: {=IFERROR(INDEX(Bets!$AE$2:$AE$73,MATCH(LARGE(Bets!$AM$2:$AM$73,8),Bets!$AM$2:$AM$73,0)),"")} -> 2.7 | G20: {=IFERROR(INDEX(Bets!$AF$2:$AF$73,MATCH(LARGE(Bets!$AM$2:$AM$73,8),Bets!$AM$2:$AM$73,0)),"")} -> 0.039558709 | H20: {=IFERROR(INDEX(Bets!$AG$2:$AG$73,MATCH(LARGE(Bets!$AM$2:$AM$73,8),Bets!$AM$2:$AM$73,0)),"")} -> 0.031600929 | I20: {=IFERROR(INDEX(Bets!$AJ$2:$AJ$73,MATCH(LARGE(Bets!$AM$2:$AM$73,8),Bets!$AM$2:$AM$73,0)),"")} -> 0
A22: MATCHDAY LEDGER — stakes & P&L by day | G22: HOUSE RULES
A23: Date | B23: Games | C23: Staked £ | D23: P&L £ | G23: · Only stake when FINAL ACTION shows 🟢 PLACE.
A24: 46184 | B24: =COUNTIF(Bets!$B$2:$B$73,$A24) -> 2 | C24: =SUMIFS(Bets!$AP$2:$AP$73,Bets!$B$2:$B$73,$A24,Bets!$AN$2:$AN$73,"Y") -> 30 | D24: =SUMIFS(Bets!$AR$2:$AR$73,Bets!$B$2:$B$73,$A24) -> 24.4 | E24: =IF(D24>0,REPT("█",MIN(25,ROUND(D24/4,0))),REPT("░",MIN(25,ROUND(-D24/4,0)))) -> ██████ | G24: · "—" or PASS on most matches = the filter working, not a fault.
A25: 46185 | B25: =COUNTIF(Bets!$B$2:$B$73,$A25) -> 2 | C25: =SUMIFS(Bets!$AP$2:$AP$73,Bets!$B$2:$B$73,$A25,Bets!$AN$2:$AN$73,"Y") -> 44 | D25: =SUMIFS(Bets!$AR$2:$AR$73,Bets!$B$2:$B$73,$A25) -> -3 | E25: =IF(D25>0,REPT("█",MIN(25,ROUND(D25/4,0))),REPT("░",MIN(25,ROUND(-D25/4,0)))) -> ░ | G25: · Fun bets are allowed — small (≤ £5), and STATUS labels them honestly.
A26: 46186 | B26: =COUNTIF(Bets!$B$2:$B$73,$A26) -> 4 | C26: =SUMIFS(Bets!$AP$2:$AP$73,Bets!$B$2:$B$73,$A26,Bets!$AN$2:$AN$73,"Y") -> 60 | D26: =SUMIFS(Bets!$AR$2:$AR$73,Bets!$B$2:$B$73,$A26) -> 42.9 | E26: =IF(D26>0,REPT("█",MIN(25,ROUND(D26/4,0))),REPT("░",MIN(25,ROUND(-D26/4,0)))) -> ███████████ | G26: · Never exceed the stake shown. Never chase a loss.
A27: 46187 | B27: =COUNTIF(Bets!$B$2:$B$73,$A27) -> 4 | C27: =SUMIFS(Bets!$AP$2:$AP$73,Bets!$B$2:$B$73,$A27,Bets!$AN$2:$AN$73,"Y") -> 6 | D27: =SUMIFS(Bets!$AR$2:$AR$73,Bets!$B$2:$B$73,$A27) -> -6 | E27: =IF(D27>0,REPT("█",MIN(25,ROUND(D27/4,0))),REPT("░",MIN(25,ROUND(-D27/4,0)))) -> ░░ | G27: · Friends: stake = "£ per £100" × (their bankroll ÷ 100).
A28: 46188 | B28: =COUNTIF(Bets!$B$2:$B$73,$A28) -> 4 | C28: =SUMIFS(Bets!$AP$2:$AP$73,Bets!$B$2:$B$73,$A28,Bets!$AN$2:$AN$73,"Y") -> 0 | D28: =SUMIFS(Bets!$AR$2:$AR$73,Bets!$B$2:$B$73,$A28) -> 0 | E28: =IF(D28>0,REPT("█",MIN(25,ROUND(D28/4,0))),REPT("░",MIN(25,ROUND(-D28/4,0)))) | G28: · 18+ · not financial advice · BeGambleAware.org
A29: 46189 | B29: =COUNTIF(Bets!$B$2:$B$73,$A29) -> 4 | C29: =SUMIFS(Bets!$AP$2:$AP$73,Bets!$B$2:$B$73,$A29,Bets!$AN$2:$AN$73,"Y") -> 0 | D29: =SUMIFS(Bets!$AR$2:$AR$73,Bets!$B$2:$B$73,$A29) -> 0 | E29: =IF(D29>0,REPT("█",MIN(25,ROUND(D29/4,0))),REPT("░",MIN(25,ROUND(-D29/4,0))))
A30: 46190 | B30: =COUNTIF(Bets!$B$2:$B$73,$A30) -> 4 | C30: =SUMIFS(Bets!$AP$2:$AP$73,Bets!$B$2:$B$73,$A30,Bets!$AN$2:$AN$73,"Y") -> 0 | D30: =SUMIFS(Bets!$AR$2:$AR$73,Bets!$B$2:$B$73,$A30) -> 0 | E30: =IF(D30>0,REPT("█",MIN(25,ROUND(D30/4,0))),REPT("░",MIN(25,ROUND(-D30/4,0))))
A31: 46191 | B31: =COUNTIF(Bets!$B$2:$B$73,$A31) -> 4 | C31: =SUMIFS(Bets!$AP$2:$AP$73,Bets!$B$2:$B$73,$A31,Bets!$AN$2:$AN$73,"Y") -> 0 | D31: =SUMIFS(Bets!$AR$2:$AR$73,Bets!$B$2:$B$73,$A31) -> 0 | E31: =IF(D31>0,REPT("█",MIN(25,ROUND(D31/4,0))),REPT("░",MIN(25,ROUND(-D31/4,0))))
A32: 46192 | B32: =COUNTIF(Bets!$B$2:$B$73,$A32) -> 4 | C32: =SUMIFS(Bets!$AP$2:$AP$73,Bets!$B$2:$B$73,$A32,Bets!$AN$2:$AN$73,"Y") -> 0 | D32: =SUMIFS(Bets!$AR$2:$AR$73,Bets!$B$2:$B$73,$A32) -> 0 | E32: =IF(D32>0,REPT("█",MIN(25,ROUND(D32/4,0))),REPT("░",MIN(25,ROUND(-D32/4,0))))
A33: 46193 | B33: =COUNTIF(Bets!$B$2:$B$73,$A33) -> 4 | C33: =SUMIFS(Bets!$AP$2:$AP$73,Bets!$B$2:$B$73,$A33,Bets!$AN$2:$AN$73,"Y") -> 0 | D33: =SUMIFS(Bets!$AR$2:$AR$73,Bets!$B$2:$B$73,$A33) -> 0 | E33: =IF(D33>0,REPT("█",MIN(25,ROUND(D33/4,0))),REPT("░",MIN(25,ROUND(-D33/4,0))))
A34: 46194 | B34: =COUNTIF(Bets!$B$2:$B$73,$A34) -> 4 | C34: =SUMIFS(Bets!$AP$2:$AP$73,Bets!$B$2:$B$73,$A34,Bets!$AN$2:$AN$73,"Y") -> 0 | D34: =SUMIFS(Bets!$AR$2:$AR$73,Bets!$B$2:$B$73,$A34) -> 0 | E34: =IF(D34>0,REPT("█",MIN(25,ROUND(D34/4,0))),REPT("░",MIN(25,ROUND(-D34/4,0))))
A35: 46195 | B35: =COUNTIF(Bets!$B$2:$B$73,$A35) -> 4 | C35: =SUMIFS(Bets!$AP$2:$AP$73,Bets!$B$2:$B$73,$A35,Bets!$AN$2:$AN$73,"Y") -> 0 | D35: =SUMIFS(Bets!$AR$2:$AR$73,Bets!$B$2:$B$73,$A35) -> 0 | E35: =IF(D35>0,REPT("█",MIN(25,ROUND(D35/4,0))),REPT("░",MIN(25,ROUND(-D35/4,0))))
A36: 46196 | B36: =COUNTIF(Bets!$B$2:$B$73,$A36) -> 4 | C36: =SUMIFS(Bets!$AP$2:$AP$73,Bets!$B$2:$B$73,$A36,Bets!$AN$2:$AN$73,"Y") -> 0 | D36: =SUMIFS(Bets!$AR$2:$AR$73,Bets!$B$2:$B$73,$A36) -> 0 | E36: =IF(D36>0,REPT("█",MIN(25,ROUND(D36/4,0))),REPT("░",MIN(25,ROUND(-D36/4,0))))
A37: 46197 | B37: =COUNTIF(Bets!$B$2:$B$73,$A37) -> 6 | C37: =SUMIFS(Bets!$AP$2:$AP$73,Bets!$B$2:$B$73,$A37,Bets!$AN$2:$AN$73,"Y") -> 0 | D37: =SUMIFS(Bets!$AR$2:$AR$73,Bets!$B$2:$B$73,$A37) -> 0 | E37: =IF(D37>0,REPT("█",MIN(25,ROUND(D37/4,0))),REPT("░",MIN(25,ROUND(-D37/4,0))))
A38: 46198 | B38: =COUNTIF(Bets!$B$2:$B$73,$A38) -> 6 | C38: =SUMIFS(Bets!$AP$2:$AP$73,Bets!$B$2:$B$73,$A38,Bets!$AN$2:$AN$73,"Y") -> 0 | D38: =SUMIFS(Bets!$AR$2:$AR$73,Bets!$B$2:$B$73,$A38) -> 0 | E38: =IF(D38>0,REPT("█",MIN(25,ROUND(D38/4,0))),REPT("░",MIN(25,ROUND(-D38/4,0))))
A39: 46199 | B39: =COUNTIF(Bets!$B$2:$B$73,$A39) -> 6 | C39: =SUMIFS(Bets!$AP$2:$AP$73,Bets!$B$2:$B$73,$A39,Bets!$AN$2:$AN$73,"Y") -> 0 | D39: =SUMIFS(Bets!$AR$2:$AR$73,Bets!$B$2:$B$73,$A39) -> 0 | E39: =IF(D39>0,REPT("█",MIN(25,ROUND(D39/4,0))),REPT("░",MIN(25,ROUND(-D39/4,0))))
A40: 46200 | B40: =COUNTIF(Bets!$B$2:$B$73,$A40) -> 6 | C40: =SUMIFS(Bets!$AP$2:$AP$73,Bets!$B$2:$B$73,$A40,Bets!$AN$2:$AN$73,"Y") -> 0 | D40: =SUMIFS(Bets!$AR$2:$AR$73,Bets!$B$2:$B$73,$A40) -> 0 | E40: =IF(D40>0,REPT("█",MIN(25,ROUND(D40/4,0))),REPT("░",MIN(25,ROUND(-D40/4,0))))

Sheet Live
A1: LIVE STATE — auto-polled from /live_state.json
A3: Source URL | B3: https://wc26-matchday-intelligence.vercel.app/live_state.json
A4: Predictions URL | B4: https://wc26-matchday-intelligence.vercel.app/predictions_live.json
A5: Intel URL | B5: https://wc26-matchday-intelligence.vercel.app/matchday_intelligence.json
A6: Field | B6: Value | C6: Mirrors to Method
A7: Last poll (UTC) | B7: 46189.585 | C7: B58
A8: Mode | B8: live | C8: B59
A9: Completed matches | B9: 16 | C9: B60
A10: Provider mode | B10: active | C10: B61
A11: Warnings (joined) | C11: B62
A12: Source | B12: api_football
A13: Last model refresh (UTC) | C13: B57
A14: Simulation rerun this tick | B14: TRUE
A15: live_state last_updated_utc | B15: 2026-06-16T13:37:22.742806+00:00
A17: STATUS | B17: =IF(B7="","⚠ Apps Script not run yet — open Extensions ▸ Apps Script ▸ run installEngine()","✓ live polling active · last poll "&TEXT(B7,"yyyy-mm-dd hh:mm")) -> ✓ live polling active · last poll 2026-06-16 14:02
A18: — MATCHDAY INTELLIGENCE (auto) —
A19: Intel generated at (UTC) | B19: 2026-06-16T11:13:56.346678+00:00 | C19: mirrors to Method!B67
A20: Intel total components | B20: 52 | C20: B68
A21: Intel teams affected | B21: 38 | C21: B69
A22: Intel matches affected | B22: 14 | C22: B70
A23: Intel aggregate caps hit | B23: 0 | C23: B71
A24: Intel warnings | B24: [object Object]
A25: Matches in play right now | B25: 0 | C25: see In-Play sheet
A26: Stale-feed warning | B26: ⚠ STALE feed (25 min old) — model paused | C26: >15 min trips PAUSE
A28: Endpoints — clear B3/B4/B5 to revert to v2.3 defaults.
A30: This sheet is read-only output from the Apps Script poller. If the values stay blank, open Extensions ▸ Apps Script and run installEngine() once. The script then refreshes model probabilities into Bets!I:K (skipping any row already flagged as Placed=Y) and writes a snapshot of /live_state.json here every 5 minutes.

Sheet Bets
A1: # | B1: Date | C1: Grp | D1: Home | E1: Away | F1: Venue | G1: KO local | H1: KO UK | I1: Model pH | J1: Model pD | K1: Model pA | L1: Odds H | M1: Odds D | N1: Odds A | O1: imp H | P1: imp D | Q1: imp A | R1: Overround | S1: mkt H | T1: mkt D | U1: mkt A | V1: blend H | W1: blend D | X1: blend A | Y1: EV H | Z1: EV D | AA1: EV A | AB1: pick# | AC1: code | AD1: PICK | AE1: Odds | AF1: EV % | AG1: Edge pp | AH1: DECISION | AI1: £ / £100 bank | AJ1: ENGINE STAKE £ | AK1: p(blend) | AL1: Kelly f | AM1: rankkey | AN1: Placed? | AO1: Odds taken | AP1: Stake £ | AQ1: Result | AR1: P&L £ | AS1: Cum P&L | AT1: WHY (plain English) | AU1: STATUS | AV1: Backed | AW1: dec@bet | AX1: eng£@bet | AY1: pick@bet | AZ1: class | BA1: eng£ eff | BB1: intel Δ | BC1: pH (cal) | BD1: pD (cal) | BE1: pA (cal) | BF1: intel breakdown | BG1: altitude m | BH1: climate | BI1: home travel km
A2: 1 | B2: 46184 | C2: A | D2: Mexico | E2: South Africa | F2: Mexico City | G2: 13:00 | H2: 20:00 | I2: 0.7008 | J2: 0.2117 | K2: 0.0876 | L2: =IF(Matchday!E4="","",Matchday!E4) -> 1.42 | M2: =IF(Matchday!F4="","",Matchday!F4) -> 4.5 | N2: =IF(Matchday!G4="","",Matchday!G4) -> 8.5 | O2: =IF(L2="","",1/L2) -> 0.70422535 | P2: =IF(M2="","",1/M2) -> 0.22222222 | Q2: =IF(N2="","",1/N2) -> 0.11764706 | R2: =IF(COUNT(L2:N2)<3,"",O2+P2+Q2) -> 1.0440946 | S2: {=IF($R2="","",IF(Method!$B$56="proportional",O2/$R2,IF(Method!$B$56="power",IFERROR(INDEX(power_devig($L2,$M2,$N2),1,1),O2/$R2),IFERROR(INDEX(shin($L2,$M2,$N2),1,1),O2/$R2))))} -> 0.68567733 | T2: {=IF($R2="","",IF(Method!$B$56="proportional",P2/$R2,IF(Method!$B$56="power",IFERROR(INDEX(power_devig($L2,$M2,$N2),2,1),P2/$R2),IFERROR(INDEX(shin($L2,$M2,$N2),2,1),P2/$R2))))} -> 0.20878432 | U2: {=IF($R2="","",IF(Method!$B$56="proportional",Q2/$R2,IF(Method!$B$56="power",IFERROR(INDEX(power_devig($L2,$M2,$N2),3,1),Q2/$R2),IFERROR(INDEX(shin($L2,$M2,$N2),3,1),Q2/$R2))))} -> 0.10553835 | V2: =IF(S2="","",Method!$B$4*I2+(1-Method!$B$4)*S2/($S2+$T2+$U2)) -> 0.69097026 | W2: =IF(T2="","",Method!$B$4*J2+(1-Method!$B$4)*T2/($S2+$T2+$U2)) -> 0.20980481 | X2: =IF(U2="","",Method!$B$4*K2+(1-Method!$B$4)*U2/($S2+$T2+$U2)) -> 0.099259929 | Y2: =IF(V2="","",V2*L2-1) -> -0.018822225 | Z2: =IF(W2="","",W2*M2-1) -> -0.055878369 | AA2: =IF(X2="","",X2*N2-1) -> -0.1562906 | AB2: =IF(Y2="","",MATCH(MAX(Y2:AA2),Y2:AA2,0)) -> 1 | AC2: =IF(AB2="","",CHOOSE(AB2,"H","D","A")) -> H | AD2: =IF(AB2="","",CHOOSE(AB2,"1 "&D2,"X Draw","2 "&E2)) -> 1 Mexico | AE2: =IF(AB2="","",INDEX(L2:N2,1,AB2)) -> 1.42 | AF2: =IF(AB2="","",INDEX(Y2:AA2,1,AB2)) -> -0.018822225 | AG2: =IF(AB2="","",INDEX(V2:X2,1,AB2)-INDEX(S2:U2,1,AB2)) -> 0.0052929349 | AH2: =IF(AB2="","· enter odds",IF(AND(AF2>=Method!$B$7,AG2>=Method!$B$8),"BET","PASS")) -> PASS | AI2: =IF(AH2<>"BET",0,ROUND(MIN(Method!$B$6,Method!$B$5*AL2)*100,1)) -> 0 | AJ2: =IF(OR(AH2<>"BET",Method!$B$55=TRUE()),0,IF(AI2*Method!$B$10/100<Method!$B$9,0,ROUND(AI2*Method!$B$10/100,0))) -> 0 | AK2: =IF(AB2="","",INDEX(V2:X2,1,AB2)) -> 0.69097026 | AL2: =IF(AH2<>"BET","",MAX(0,(AK2*AE2-1)/(AE2-1))) | AM2: =IF(AH2="BET",AF2+A2/1000000,"") | AN2: =IF(Matchday!N4="","",Matchday!N4) -> Y | AO2: =IF(Matchday!P4="","",Matchday!P4) -> 1.42 | AP2: =IF(Matchday!Q4="","",Matchday!Q4) -> 20 | AQ2: =IF(Matchday!R4="","",Matchday!R4) -> H | AR2: =IF(OR(AN2<>"Y",AQ2="",AV2=""),"",IF(AQ2="Void",0,IF(AQ2=AV2,ROUND(AP2*(AO2-1),2),-AP2))) -> 8.4 | AS2: =IF(AR2="","",SUM($AR$2:AR2)) -> 8.4 | AT2: =IF(AB2="","Type the 3 odds on the Matchday tab",IF(Method!$B$55=TRUE(),"🛑 PAUSED — drawdown "&TEXT(Method!$B$51,"0.0%")&" ≥ "&TEXT(Method!$B$52,"0.0%")&". Set Method!B54=Y to override.",IF(AH2="BET",IF(AJ2=0,"Edge found but stake rounds under £"&Method!$B$9&" — skip","Value found: EV "&TEXT(AF2,"0.0%")&", edge "&TEXT(AG2,"0.0%")),IF(AF2<Method!$B$7,"Price too short — EV "&TEXT(AF2,"0.0%")&" (need "&TEXT(Method!$B$7,"0.0%")&"+)","Model ≈ market — edge "&TEXT(AG2,"0.0%")&" (need "&TEXT(Method!$B$8,"0.0%")&"+)")))) -> 🛑 PAUSED — drawdown 0.6% ≥ 15.0%. Set Method!B54=Y to override. | AU2: =IF(AN2<>"Y","",IF(AH2="· enter odds","⚠ type the 3 odds (1/X/2) to grade this bet",IF(OR(AV2="",AO2="",AP2=""),"⚠ log backed pick, odds & stake",IF(AZ2<>"BET","⚠ FUN BET — engine said pass · staked £"&AP2&" vs engine £"&BA2,IF(AV2<>IF(AY2="",AC2,AY2),"⚠ backed "&AV2&" but engine pick was "&IF(AY2="",AC2,AY2),IF(AP2>BA2,"⚠ stake over engine £"&BA2,IF(ABS(AO2-IFERROR(INDEX(L2:N2,1,MATCH(AV2,{"H","D","A"},0)),AE2))>0.02,"⚠ odds moved — re-check value","✓ engine bet"))))))) -> ⚠ FUN BET — engine said pass · staked £20 vs engine £0 | AV2: =IF(Matchday!O4="","",Matchday!O4) -> H | AW2: PASS | AX2: 0 | AY2: H | AZ2: =IF(AW2="",AH2,AW2) -> PASS | BA2: =IF(AX2<>"",AX2,IF(AH2<>"BET",0,IF(AI2*Method!$B$10/100<Method!$B$9,0,ROUND(AI2*Method!$B$10/100,0)))) -> 0 | BB2: 0 | BC2: 0.650274 | BD2: 0.23507441 | BE2: 0.088686139 | BG2: 2240 | BH2: high_altitude_mild | BI2: 0
A3: 2 | B3: 46184 | C3: A | D3: South Korea | E3: Czechia | F3: Zapopan | G3: 20:00 | H3: 03:00 +1d | I3: 0.44370918 | J3: 0.29067093 | K3: 0.26561988 | L3: =IF(Matchday!E5="","",Matchday!E5) -> 2.7 | M3: =IF(Matchday!F5="","",Matchday!F5) -> 3.1 | N3: =IF(Matchday!G5="","",Matchday!G5) -> 2.8 | O3: =IF(L3="","",1/L3) -> 0.37037037 | P3: =IF(M3="","",1/M3) -> 0.32258065 | Q3: =IF(N3="","",1/N3) -> 0.35714286 | R3: =IF(COUNT(L3:N3)<3,"",O3+P3+Q3) -> 1.0500939 | S3: {=IF($R3="","",IF(Method!$B$56="proportional",O3/$R3,IF(Method!$B$56="power",IFERROR(INDEX(power_devig($L3,$M3,$N3),1,1),O3/$R3),IFERROR(INDEX(shin($L3,$M3,$N3),1,1),O3/$R3))))} -> 0.35342082 | T3: {=IF($R3="","",IF(Method!$B$56="proportional",P3/$R3,IF(Method!$B$56="power",IFERROR(INDEX(power_devig($L3,$M3,$N3),2,1),P3/$R3),IFERROR(INDEX(shin($L3,$M3,$N3),2,1),P3/$R3))))} -> 0.30622296 | U3: {=IF($R3="","",IF(Method!$B$56="proportional",Q3/$R3,IF(Method!$B$56="power",IFERROR(INDEX(power_devig($L3,$M3,$N3),3,1),Q3/$R3),IFERROR(INDEX(shin($L3,$M3,$N3),3,1),Q3/$R3))))} -> 0.34035623 | V3: =IF(S3="","",Method!$B$4*I3+(1-Method!$B$4)*S3/($S3+$T3+$U3)) -> 0.38502174 | W3: =IF(T3="","",Method!$B$4*J3+(1-Method!$B$4)*T3/($S3+$T3+$U3)) -> 0.30077975 | X3: =IF(U3="","",Method!$B$4*K3+(1-Method!$B$4)*U3/($S3+$T3+$U3)) -> 0.31419851 | Y3: =IF(V3="","",V3*L3-1) -> 0.039558709 | Z3: =IF(W3="","",W3*M3-1) -> -0.067582783 | AA3: =IF(X3="","",X3*N3-1) -> -0.12024418 | AB3: =IF(Y3="","",MATCH(MAX(Y3:AA3),Y3:AA3,0)) -> 1 | AC3: =IF(AB3="","",CHOOSE(AB3,"H","D","A")) -> H | AD3: =IF(AB3="","",CHOOSE(AB3,"1 "&D3,"X Draw","2 "&E3)) -> 1 South Korea | AE3: =IF(AB3="","",INDEX(L3:N3,1,AB3)) -> 2.7 | AF3: =IF(AB3="","",INDEX(Y3:AA3,1,AB3)) -> 0.039558709 | AG3: =IF(AB3="","",INDEX(V3:X3,1,AB3)-INDEX(S3:U3,1,AB3)) -> 0.031600929 | AH3: =IF(AB3="","· enter odds",IF(AND(AF3>=Method!$B$7,AG3>=Method!$B$8),"BET","PASS")) -> BET | AI3: =IF(AH3<>"BET",0,ROUND(MIN(Method!$B$6,Method!$B$5*AL3)*100,1)) -> 0.6 | AJ3: =IF(OR(AH3<>"BET",Method!$B$55=TRUE()),0,IF(AI3*Method!$B$10/100<Method!$B$9,0,ROUND(AI3*Method!$B$10/100,0))) -> 0 | AK3: =IF(AB3="","",INDEX(V3:X3,1,AB3)) -> 0.38502174 | AL3: =IF(AH3<>"BET","",MAX(0,(AK3*AE3-1)/(AE3-1))) -> 0.023269829 | AM3: =IF(AH3="BET",AF3+A3/1000000,"") -> 0.039560709 | AN3: =IF(Matchday!N5="","",Matchday!N5) -> Y | AO3: =IF(Matchday!P5="","",Matchday!P5) -> 2.6 | AP3: =IF(Matchday!Q5="","",Matchday!Q5) -> 10 | AQ3: =IF(Matchday!R5="","",Matchday!R5) -> H | AR3: =IF(OR(AN3<>"Y",AQ3="",AV3=""),"",IF(AQ3="Void",0,IF(AQ3=AV3,ROUND(AP3*(AO3-1),2),-AP3))) -> 16 | AS3: =IF(AR3="","",SUM($AR$2:AR3)) -> 24.4 | AT3: =IF(AB3="","Type the 3 odds on the Matchday tab",IF(Method!$B$55=TRUE(),"🛑 PAUSED — drawdown "&TEXT(Method!$B$51,"0.0%")&" ≥ "&TEXT(Method!$B$52,"0.0%")&". Set Method!B54=Y to override.",IF(AH3="BET",IF(AJ3=0,"Edge found but stake rounds under £"&Method!$B$9&" — skip","Value found: EV "&TEXT(AF3,"0.0%")&", edge "&TEXT(AG3,"0.0%")),IF(AF3<Method!$B$7,"Price too short — EV "&TEXT(AF3,"0.0%")&" (need "&TEXT(Method!$B$7,"0.0%")&"+)","Model ≈ market — edge "&TEXT(AG3,"0.0%")&" (need "&TEXT(Method!$B$8,"0.0%")&"+)")))) -> 🛑 PAUSED — drawdown 0.6% ≥ 15.0%. Set Method!B54=Y to override. | AU3: =IF(AN3<>"Y","",IF(AH3="· enter odds","⚠ type the 3 odds (1/X/2) to grade this bet",IF(OR(AV3="",AO3="",AP3=""),"⚠ log backed pick, odds & stake",IF(AZ3<>"BET","⚠ FUN BET — engine said pass · staked £"&AP3&" vs engine £"&BA3,IF(AV3<>IF(AY3="",AC3,AY3),"⚠ backed "&AV3&" but engine pick was "&IF(AY3="",AC3,AY3),IF(AP3>BA3,"⚠ stake over engine £"&BA3,IF(ABS(AO3-IFERROR(INDEX(L3:N3,1,MATCH(AV3,{"H","D","A"},0)),AE3))>0.02,"⚠ odds moved — re-check value","✓ engine bet"))))))) -> ⚠ stake over engine £3 | AV3: =IF(Matchday!O5="","",Matchday!O5) -> H | AW3: BET | AX3: 3 | AY3: H | AZ3: =IF(AW3="",AH3,AW3) -> BET | BA3: =IF(AX3<>"",AX3,IF(AH3<>"BET",0,IF(AI3*Method!$B$10/100<Method!$B$9,0,ROUND(AI3*Method!$B$10/100,0)))) -> 3 | BB3: -5 | BC3: 0.42788052 | BD3: 0.29013376 | BE3: 0.2706498 | BF3: Czechia weather: -4 · South Korea weather: -1 | BG3: 1560 | BH3: warm_humid | BI3: 0
A4: 3 | B4: 46185 | C4: B | D4: Canada | E4: Bosnia and Herzegovina | F4: Toronto | G4: 15:00 | H4: 20:00 | I4: 0.69750662 | J4: 0.2132834 | K4: 0.089209979 | L4: =IF(Matchday!E6="","",Matchday!E6) -> 1.85 | M4: =IF(Matchday!F6="","",Matchday!F6) -> 3.5 | N4: =IF(Matchday!G6="","",Matchday!G6) -> 4.5 | O4: =IF(L4="","",1/L4) -> 0.54054054 | P4: =IF(M4="","",1/M4) -> 0.28571429 | Q4: =IF(N4="","",1/N4) -> 0.22222222 | R4: =IF(COUNT(L4:N4)<3,"",O4+P4+Q4) -> 1.048477 | S4: {=IF($R4="","",IF(Method!$B$56="proportional",O4/$R4,IF(Method!$B$56="power",IFERROR(INDEX(power_devig($L4,$M4,$N4),1,1),O4/$R4),IFERROR(INDEX(shin($L4,$M4,$N4),1,1),O4/$R4))))} -> 0.52211289 | T4: {=IF($R4="","",IF(Method!$B$56="proportional",P4/$R4,IF(Method!$B$56="power",IFERROR(INDEX(power_devig($L4,$M4,$N4),2,1),P4/$R4),IFERROR(INDEX(shin($L4,$M4,$N4),2,1),P4/$R4))))} -> 0.27029207 | U4: {=IF($R4="","",IF(Method!$B$56="proportional",Q4/$R4,IF(Method!$B$56="power",IFERROR(INDEX(power_devig($L4,$M4,$N4),3,1),Q4/$R4),IFERROR(INDEX(shin($L4,$M4,$N4),3,1),Q4/$R4))))} -> 0.20759504 | V4: =IF(S4="","",Method!$B$4*I4+(1-Method!$B$4)*S4/($S4+$T4+$U4)) -> 0.58350069 | W4: =IF(T4="","",Method!$B$4*J4+(1-Method!$B$4)*T4/($S4+$T4+$U4)) -> 0.25033904 | X4: =IF(U4="","",Method!$B$4*K4+(1-Method!$B$4)*U4/($S4+$T4+$U4)) -> 0.16616027 | Y4: =IF(V4="","",V4*L4-1) -> 0.079476281 | Z4: =IF(W4="","",W4*M4-1) -> -0.12381337 | AA4: =IF(X4="","",X4*N4-1) -> -0.25227878 | AB4: =IF(Y4="","",MATCH(MAX(Y4:AA4),Y4:AA4,0)) -> 1 | AC4: =IF(AB4="","",CHOOSE(AB4,"H","D","A")) -> H | AD4: =IF(AB4="","",CHOOSE(AB4,"1 "&D4,"X Draw","2 "&E4)) -> 1 Canada | AE4: =IF(AB4="","",INDEX(L4:N4,1,AB4)) -> 1.85 | AF4: =IF(AB4="","",INDEX(Y4:AA4,1,AB4)) -> 0.079476281 | AG4: =IF(AB4="","",INDEX(V4:X4,1,AB4)-INDEX(S4:U4,1,AB4)) -> 0.061387805 | AH4: =IF(AB4="","· enter odds",IF(AND(AF4>=Method!$B$7,AG4>=Method!$B$8),"BET","PASS")) -> BET | AI4: =IF(AH4<>"BET",0,ROUND(MIN(Method!$B$6,Method!$B$5*AL4)*100,1)) -> 2.3 | AJ4: =IF(OR(AH4<>"BET",Method!$B$55=TRUE()),0,IF(AI4*Method!$B$10/100<Method!$B$9,0,ROUND(AI4*Method!$B$10/100,0))) -> 0 | AK4: =IF(AB4="","",INDEX(V4:X4,1,AB4)) -> 0.58350069 | AL4: =IF(AH4<>"BET","",MAX(0,(AK4*AE4-1)/(AE4-1))) -> 0.093501507 | AM4: =IF(AH4="BET",AF4+A4/1000000,"") -> 0.079479281 | AN4: =IF(Matchday!N6="","",Matchday!N6) -> Y | AO4: =IF(Matchday!P6="","",Matchday!P6) -> 1.85 | AP4: =IF(Matchday!Q6="","",Matchday!Q6) -> 24 | AQ4: =IF(Matchday!R6="","",Matchday!R6) -> D | AR4: =IF(OR(AN4<>"Y",AQ4="",AV4=""),"",IF(AQ4="Void",0,IF(AQ4=AV4,ROUND(AP4*(AO4-1),2),-AP4))) -> -24 | AS4: =IF(AR4="","",SUM($AR$2:AR4)) -> 0.4 | AT4: =IF(AB4="","Type the 3 odds on the Matchday tab",IF(Method!$B$55=TRUE(),"🛑 PAUSED — drawdown "&TEXT(Method!$B$51,"0.0%")&" ≥ "&TEXT(Method!$B$52,"0.0%")&". Set Method!B54=Y to override.",IF(AH4="BET",IF(AJ4=0,"Edge found but stake rounds under £"&Method!$B$9&" — skip","Value found: EV "&TEXT(AF4,"0.0%")&", edge "&TEXT(AG4,"0.0%")),IF(AF4<Method!$B$7,"Price too short — EV "&TEXT(AF4,"0.0%")&" (need "&TEXT(Method!$B$7,"0.0%")&"+)","Model ≈ market — edge "&TEXT(AG4,"0.0%")&" (need "&TEXT(Method!$B$8,"0.0%")&"+)")))) -> 🛑 PAUSED — drawdown 0.6% ≥ 15.0%. Set Method!B54=Y to override. | AU4: =IF(AN4<>"Y","",IF(AH4="· enter odds","⚠ type the 3 odds (1/X/2) to grade this bet",IF(OR(AV4="",AO4="",AP4=""),"⚠ log backed pick, odds & stake",IF(AZ4<>"BET","⚠ FUN BET — engine said pass · staked £"&AP4&" vs engine £"&BA4,IF(AV4<>IF(AY4="",AC4,AY4),"⚠ backed "&AV4&" but engine pick was "&IF(AY4="",AC4,AY4),IF(AP4>BA4,"⚠ stake over engine £"&BA4,IF(ABS(AO4-IFERROR(INDEX(L4:N4,1,MATCH(AV4,{"H","D","A"},0)),AE4))>0.02,"⚠ odds moved — re-check value","✓ engine bet"))))))) -> ⚠ stake over engine £12 | AV4: =IF(Matchday!O6="","",Matchday!O6) -> H | AW4: BET | AX4: 12 | AY4: H | AZ4: =IF(AW4="",AH4,AW4) -> BET | BA4: =IF(AX4<>"",AX4,IF(AH4<>"BET",0,IF(AI4*Method!$B$10/100<Method!$B$9,0,ROUND(AI4*Method!$B$10/100,0)))) -> 12 | BB4: 0 | BC4: 0.64681174 | BD4: 0.23660731 | BE4: 0.090414781 | BG4: 76 | BH4: mild | BI4: 0
A5: 4 | B5: 46185 | C5: D | D5: United States | E5: Paraguay | F5: Inglewood | G5: 18:00 | H5: 02:00 +1d | I5: 0.48548732 | J5: 0.2800987 | K5: 0.23441398 | L5: =IF(Matchday!E7="","",Matchday!E7) -> 2.18 | M5: =IF(Matchday!F7="","",Matchday!F7) -> 3.3 | N5: =IF(Matchday!G7="","",Matchday!G7) -> 4.1 | O5: =IF(L5="","",1/L5) -> 0.4587156 | P5: =IF(M5="","",1/M5) -> 0.3030303 | Q5: =IF(N5="","",1/N5) -> 0.24390244 | R5: =IF(COUNT(L5:N5)<3,"",O5+P5+Q5) -> 1.0056483 | S5: {=IF($R5="","",IF(Method!$B$56="proportional",O5/$R5,IF(Method!$B$56="power",IFERROR(INDEX(power_devig($L5,$M5,$N5),1,1),O5/$R5),IFERROR(INDEX(shin($L5,$M5,$N5),1,1),O5/$R5))))} -> 0.4566588 | T5: {=IF($R5="","",IF(Method!$B$56="proportional",P5/$R5,IF(Method!$B$56="power",IFERROR(INDEX(power_devig($L5,$M5,$N5),2,1),P5/$R5),IFERROR(INDEX(shin($L5,$M5,$N5),2,1),P5/$R5))))} -> 0.30119272 | U5: {=IF($R5="","",IF(Method!$B$56="proportional",Q5/$R5,IF(Method!$B$56="power",IFERROR(INDEX(power_devig($L5,$M5,$N5),3,1),Q5/$R5),IFERROR(INDEX(shin($L5,$M5,$N5),3,1),Q5/$R5))))} -> 0.24214849 | V5: =IF(S5="","",Method!$B$4*I5+(1-Method!$B$4)*S5/($S5+$T5+$U5)) -> 0.46674878 | W5: =IF(T5="","",Method!$B$4*J5+(1-Method!$B$4)*T5/($S5+$T5+$U5)) -> 0.29380981 | X5: =IF(U5="","",Method!$B$4*K5+(1-Method!$B$4)*U5/($S5+$T5+$U5)) -> 0.23944141 | Y5: =IF(V5="","",V5*L5-1) -> 0.01751234 | Z5: =IF(W5="","",W5*M5-1) -> -0.030427623 | AA5: =IF(X5="","",X5*N5-1) -> -0.018290222 | AB5: =IF(Y5="","",MATCH(MAX(Y5:AA5),Y5:AA5,0)) -> 1 | AC5: =IF(AB5="","",CHOOSE(AB5,"H","D","A")) -> H | AD5: =IF(AB5="","",CHOOSE(AB5,"1 "&D5,"X Draw","2 "&E5)) -> 1 United States | AE5: =IF(AB5="","",INDEX(L5:N5,1,AB5)) -> 2.18 | AF5: =IF(AB5="","",INDEX(Y5:AA5,1,AB5)) -> 0.01751234 | AG5: =IF(AB5="","",INDEX(V5:X5,1,AB5)-INDEX(S5:U5,1,AB5)) -> 0.010089984 | AH5: =IF(AB5="","· enter odds",IF(AND(AF5>=Method!$B$7,AG5>=Method!$B$8),"BET","PASS")) -> PASS | AI5: =IF(AH5<>"BET",0,ROUND(MIN(Method!$B$6,Method!$B$5*AL5)*100,1)) -> 0 | AJ5: =IF(OR(AH5<>"BET",Method!$B$55=TRUE()),0,IF(AI5*Method!$B$10/100<Method!$B$9,0,ROUND(AI5*Method!$B$10/100,0))) -> 0 | AK5: =IF(AB5="","",INDEX(V5:X5,1,AB5)) -> 0.46674878 | AL5: =IF(AH5<>"BET","",MAX(0,(AK5*AE5-1)/(AE5-1))) | AM5: =IF(AH5="BET",AF5+A5/1000000,"") | AN5: =IF(Matchday!N7="","",Matchday!N7) -> Y | AO5: =IF(Matchday!P7="","",Matchday!P7) -> 2.05 | AP5: =IF(Matchday!Q7="","",Matchday!Q7) -> 20 | AQ5: =IF(Matchday!R7="","",Matchday!R7) -> H | AR5: =IF(OR(AN5<>"Y",AQ5="",AV5=""),"",IF(AQ5="Void",0,IF(AQ5=AV5,ROUND(AP5*(AO5-1),2),-AP5))) -> 21 | AS5: =IF(AR5="","",SUM($AR$2:AR5)) -> 21.4 | AT5: =IF(AB5="","Type the 3 odds on the Matchday tab",IF(Method!$B$55=TRUE(),"🛑 PAUSED — drawdown "&TEXT(Method!$B$51,"0.0%")&" ≥ "&TEXT(Method!$B$52,"0.0%")&". Set Method!B54=Y to override.",IF(AH5="BET",IF(AJ5=0,"Edge found but stake rounds under £"&Method!$B$9&" — skip","Value found: EV "&TEXT(AF5,"0.0%")&", edge "&TEXT(AG5,"0.0%")),IF(AF5<Method!$B$7,"Price too short — EV "&TEXT(AF5,"0.0%")&" (need "&TEXT(Method!$B$7,"0.0%")&"+)","Model ≈ market — edge "&TEXT(AG5,"0.0%")&" (need "&TEXT(Method!$B$8,"0.0%")&"+)")))) -> 🛑 PAUSED — drawdown 0.6% ≥ 15.0%. Set Method!B54=Y to override. | AU5: =IF(AN5<>"Y","",IF(AH5="· enter odds","⚠ type the 3 odds (1/X/2) to grade this bet",IF(OR(AV5="",AO5="",AP5=""),"⚠ log backed pick, odds & stake",IF(AZ5<>"BET","⚠ FUN BET — engine said pass · staked £"&AP5&" vs engine £"&BA5,IF(AV5<>IF(AY5="",AC5,AY5),"⚠ backed "&AV5&" but engine pick was "&IF(AY5="",AC5,AY5),IF(AP5>BA5,"⚠ stake over engine £"&BA5,IF(ABS(AO5-IFERROR(INDEX(L5:N5,1,MATCH(AV5,{"H","D","A"},0)),AE5))>0.02,"⚠ odds moved — re-check value","✓ engine bet"))))))) -> ⚠ FUN BET — engine said pass · staked £20 vs engine £0 | AV5: =IF(Matchday!O7="","",Matchday!O7) -> H | AW5: PASS | AX5: 0 | AY5: H | AZ5: =IF(AW5="",AH5,AW5) -> PASS | BA5: =IF(AX5<>"",AX5,IF(AH5<>"BET",0,IF(AI5*Method!$B$10/100<Method!$B$9,0,ROUND(AI5*Method!$B$10/100,0)))) -> 0 | BB5: 0 | BC5: 0.46952562 | BD5: 0.28613659 | BE5: 0.23853258 | BG5: 30 | BH5: warm_dry_indoor | BI5: 0
A6: 5 | B6: 46186 | C6: B | D6: Qatar | E6: Switzerland | F6: Santa Clara | G6: 12:00 | H6: 20:00 | I6: 0.07585287 | J6: 0.19789443 | K6: 0.7262527 | L6: =IF(Matchday!E8="","",Matchday!E8) -> 14 | M6: =IF(Matchday!F8="","",Matchday!F8) -> 7.5 | N6: =IF(Matchday!G8="","",Matchday!G8) -> 1.2 | O6: =IF(L6="","",1/L6) -> 0.071428571 | P6: =IF(M6="","",1/M6) -> 0.13333333 | Q6: =IF(N6="","",1/N6) -> 0.83333333 | R6: =IF(COUNT(L6:N6)<3,"",O6+P6+Q6) -> 1.0380952 | S6: {=IF($R6="","",IF(Method!$B$56="proportional",O6/$R6,IF(Method!$B$56="power",IFERROR(INDEX(power_devig($L6,$M6,$N6),1,1),O6/$R6),IFERROR(INDEX(shin($L6,$M6,$N6),1,1),O6/$R6))))} -> 0.061439258 | T6: {=IF($R6="","",IF(Method!$B$56="proportional",P6/$R6,IF(Method!$B$56="power",IFERROR(INDEX(power_devig($L6,$M6,$N6),2,1),P6/$R6),IFERROR(INDEX(shin($L6,$M6,$N6),2,1),P6/$R6))))} -> 0.12247683 | U6: {=IF($R6="","",IF(Method!$B$56="proportional",Q6/$R6,IF(Method!$B$56="power",IFERROR(INDEX(power_devig($L6,$M6,$N6),3,1),Q6/$R6),IFERROR(INDEX(shin($L6,$M6,$N6),3,1),Q6/$R6))))} -> 0.81608391 | V6: =IF(S6="","",Method!$B$4*I6+(1-Method!$B$4)*S6/($S6+$T6+$U6)) -> 0.066484022 | W6: =IF(T6="","",Method!$B$4*J6+(1-Method!$B$4)*T6/($S6+$T6+$U6)) -> 0.14887299 | X6: =IF(U6="","",Method!$B$4*K6+(1-Method!$B$4)*U6/($S6+$T6+$U6)) -> 0.78464298 | Y6: =IF(V6="","",V6*L6-1) -> -0.069223691 | Z6: =IF(W6="","",W6*M6-1) -> 0.11654745 | AA6: =IF(X6="","",X6*N6-1) -> -0.058428418 | AB6: =IF(Y6="","",MATCH(MAX(Y6:AA6),Y6:AA6,0)) -> 2 | AC6: =IF(AB6="","",CHOOSE(AB6,"H","D","A")) -> D | AD6: =IF(AB6="","",CHOOSE(AB6,"1 "&D6,"X Draw","2 "&E6)) -> X Draw | AE6: =IF(AB6="","",INDEX(L6:N6,1,AB6)) -> 7.5 | AF6: =IF(AB6="","",INDEX(Y6:AA6,1,AB6)) -> 0.11654745 | AG6: =IF(AB6="","",INDEX(V6:X6,1,AB6)-INDEX(S6:U6,1,AB6)) -> 0.026396158 | AH6: =IF(AB6="","· enter odds",IF(AND(AF6>=Method!$B$7,AG6>=Method!$B$8),"BET","PASS")) -> BET | AI6: =IF(AH6<>"BET",0,ROUND(MIN(Method!$B$6,Method!$B$5*AL6)*100,1)) -> 0.4 | AJ6: =IF(OR(AH6<>"BET",Method!$B$55=TRUE()),0,IF(AI6*Method!$B$10/100<Method!$B$9,0,ROUND(AI6*Method!$B$10/100,0))) -> 0 | AK6: =IF(AB6="","",INDEX(V6:X6,1,AB6)) -> 0.14887299 | AL6: =IF(AH6<>"BET","",MAX(0,(AK6*AE6-1)/(AE6-1))) -> 0.017930377 | AM6: =IF(AH6="BET",AF6+A6/1000000,"") -> 0.11655245 | AN6: =IF(Matchday!N8="","",Matchday!N8) -> Y | AO6: =IF(Matchday!P8="","",Matchday!P8) -> 7.5 | AP6: =IF(Matchday!Q8="","",Matchday!Q8) -> 20 | AQ6: =IF(Matchday!R8="","",Matchday!R8) -> D | AR6: =IF(OR(AN6<>"Y",AQ6="",AV6=""),"",IF(AQ6="Void",0,IF(AQ6=AV6,ROUND(AP6*(AO6-1),2),-AP6))) -> -20 | AS6: =IF(AR6="","",SUM($AR$2:AR6)) -> 1.4 | AT6: =IF(AB6="","Type the 3 odds on the Matchday tab",IF(Method!$B$55=TRUE(),"🛑 PAUSED — drawdown "&TEXT(Method!$B$51,"0.0%")&" ≥ "&TEXT(Method!$B$52,"0.0%")&". Set Method!B54=Y to override.",IF(AH6="BET",IF(AJ6=0,"Edge found but stake rounds under £"&Method!$B$9&" — skip","Value found: EV "&TEXT(AF6,"0.0%")&", edge "&TEXT(AG6,"0.0%")),IF(AF6<Method!$B$7,"Price too short — EV "&TEXT(AF6,"0.0%")&" (need "&TEXT(Method!$B$7,"0.0%")&"+)","Model ≈ market — edge "&TEXT(AG6,"0.0%")&" (need "&TEXT(Method!$B$8,"0.0%")&"+)")))) -> 🛑 PAUSED — drawdown 0.6% ≥ 15.0%. Set Method!B54=Y to override. | AU6: =IF(AN6<>"Y","",IF(AH6="· enter odds","⚠ type the 3 odds (1/X/2) to grade this bet",IF(OR(AV6="",AO6="",AP6=""),"⚠ log backed pick, odds & stake",IF(AZ6<>"BET","⚠ FUN BET — engine said pass · staked £"&AP6&" vs engine £"&BA6,IF(AV6<>IF(AY6="",AC6,AY6),"⚠ backed "&AV6&" but engine pick was "&IF(AY6="",AC6,AY6),IF(AP6>BA6,"⚠ stake over engine £"&BA6,IF(ABS(AO6-IFERROR(INDEX(L6:N6,1,MATCH(AV6,{"H","D","A"},0)),AE6))>0.02,"⚠ odds moved — re-check value","✓ engine bet"))))))) -> ⚠ FUN BET — engine said pass · staked £20 vs engine £0 | AV6: =IF(Matchday!O8="","",Matchday!O8) -> A | AW6: PASS | AX6: 0 | AY6: D | AZ6: =IF(AW6="",AH6,AW6) -> PASS | BA6: =IF(AX6<>"",AX6,IF(AH6<>"BET",0,IF(AI6*Method!$B$10/100<Method!$B$9,0,ROUND(AI6*Method!$B$10/100,0)))) -> 0 | BB6: 0 | BC6: 0.069112865 | BD6: 0.22170919 | BE6: 0.70571282 | BG6: 8 | BH6: mild_dry | BI6: 0
A7: 6 | B7: 46186 | C7: C | D7: Brazil | E7: Morocco | F7: East Rutherford | G7: 18:00 | H7: 23:00 | I7: 0.45124668 | J7: 0.29136359 | K7: 0.25738973 | L7: =IF(Matchday!E9="","",Matchday!E9) -> 1.7 | M7: =IF(Matchday!F9="","",Matchday!F9) -> 3.75 | N7: =IF(Matchday!G9="","",Matchday!G9) -> 5.5 | O7: =IF(L7="","",1/L7) -> 0.58823529 | P7: =IF(M7="","",1/M7) -> 0.26666667 | Q7: =IF(N7="","",1/N7) -> 0.18181818 | R7: =IF(COUNT(L7:N7)<3,"",O7+P7+Q7) -> 1.0367201 | S7: {=IF($R7="","",IF(Method!$B$56="proportional",O7/$R7,IF(Method!$B$56="power",IFERROR(INDEX(power_devig($L7,$M7,$N7),1,1),O7/$R7),IFERROR(INDEX(shin($L7,$M7,$N7),1,1),O7/$R7))))} -> 0.57380303 | T7: {=IF($R7="","",IF(Method!$B$56="proportional",P7/$R7,IF(Method!$B$56="power",IFERROR(INDEX(power_devig($L7,$M7,$N7),2,1),P7/$R7),IFERROR(INDEX(shin($L7,$M7,$N7),2,1),P7/$R7))))} -> 0.25511569 | U7: {=IF($R7="","",IF(Method!$B$56="proportional",Q7/$R7,IF(Method!$B$56="power",IFERROR(INDEX(power_devig($L7,$M7,$N7),3,1),Q7/$R7),IFERROR(INDEX(shin($L7,$M7,$N7),3,1),Q7/$R7))))} -> 0.17108129 | V7: =IF(S7="","",Method!$B$4*I7+(1-Method!$B$4)*S7/($S7+$T7+$U7)) -> 0.5309083 | W7: =IF(T7="","",Method!$B$4*J7+(1-Method!$B$4)*T7/($S7+$T7+$U7)) -> 0.26780245 | X7: =IF(U7="","",Method!$B$4*K7+(1-Method!$B$4)*U7/($S7+$T7+$U7)) -> 0.20128924 | Y7: =IF(V7="","",V7*L7-1) -> -0.097455883 | Z7: =IF(W7="","",W7*M7-1) -> 0.004259198 | AA7: =IF(X7="","",X7*N7-1) -> 0.10709084 | AB7: =IF(Y7="","",MATCH(MAX(Y7:AA7),Y7:AA7,0)) -> 3 | AC7: =IF(AB7="","",CHOOSE(AB7,"H","D","A")) -> A | AD7: =IF(AB7="","",CHOOSE(AB7,"1 "&D7,"X Draw","2 "&E7)) -> 2 Morocco | AE7: =IF(AB7="","",INDEX(L7:N7,1,AB7)) -> 5.5 | AF7: =IF(AB7="","",INDEX(Y7:AA7,1,AB7)) -> 0.10709084 | AG7: =IF(AB7="","",INDEX(V7:X7,1,AB7)-INDEX(S7:U7,1,AB7)) -> 0.030207955 | AH7: =IF(AB7="","· enter odds",IF(AND(AF7>=Method!$B$7,AG7>=Method!$B$8),"BET","PASS")) -> BET | AI7: =IF(AH7<>"BET",0,ROUND(MIN(Method!$B$6,Method!$B$5*AL7)*100,1)) -> 0.6 | AJ7: =IF(OR(AH7<>"BET",Method!$B$55=TRUE()),0,IF(AI7*Method!$B$10/100<Method!$B$9,0,ROUND(AI7*Method!$B$10/100,0))) -> 0 | AK7: =IF(AB7="","",INDEX(V7:X7,1,AB7)) -> 0.20128924 | AL7: =IF(AH7<>"BET","",MAX(0,(AK7*AE7-1)/(AE7-1))) -> 0.023797964 | AM7: =IF(AH7="BET",AF7+A7/1000000,"") -> 0.10709684 | AN7: =IF(Matchday!N9="","",Matchday!N9) -> Y | AO7: =IF(Matchday!P9="","",Matchday!P9) -> 1.68 | AP7: =IF(Matchday!Q9="","",Matchday!Q9) -> 30 | AQ7: =IF(Matchday!R9="","",Matchday!R9) -> H | AR7: =IF(OR(AN7<>"Y",AQ7="",AV7=""),"",IF(AQ7="Void",0,IF(AQ7=AV7,ROUND(AP7*(AO7-1),2),-AP7))) -> 20.4 | AS7: =IF(AR7="","",SUM($AR$2:AR7)) -> 21.8 | AT7: =IF(AB7="","Type the 3 odds on the Matchday tab",IF(Method!$B$55=TRUE(),"🛑 PAUSED — drawdown "&TEXT(Method!$B$51,"0.0%")&" ≥ "&TEXT(Method!$B$52,"0.0%")&". Set Method!B54=Y to override.",IF(AH7="BET",IF(AJ7=0,"Edge found but stake rounds under £"&Method!$B$9&" — skip","Value found: EV "&TEXT(AF7,"0.0%")&", edge "&TEXT(AG7,"0.0%")),IF(AF7<Method!$B$7,"Price too short — EV "&TEXT(AF7,"0.0%")&" (need "&TEXT(Method!$B$7,"0.0%")&"+)","Model ≈ market — edge "&TEXT(AG7,"0.0%")&" (need "&TEXT(Method!$B$8,"0.0%")&"+)")))) -> 🛑 PAUSED — drawdown 0.6% ≥ 15.0%. Set Method!B54=Y to override. | AU7: =IF(AN7<>"Y","",IF(AH7="· enter odds","⚠ type the 3 odds (1/X/2) to grade this bet",IF(OR(AV7="",AO7="",AP7=""),"⚠ log backed pick, odds & stake",IF(AZ7<>"BET","⚠ FUN BET — engine said pass · staked £"&AP7&" vs engine £"&BA7,IF(AV7<>IF(AY7="",AC7,AY7),"⚠ backed "&AV7&" but engine pick was "&IF(AY7="",AC7,AY7),IF(AP7>BA7,"⚠ stake over engine £"&BA7,IF(ABS(AO7-IFERROR(INDEX(L7:N7,1,MATCH(AV7,{"H","D","A"},0)),AE7))>0.02,"⚠ odds moved — re-check value","✓ engine bet"))))))) -> ⚠ backed H but engine pick was A | AV7: =IF(Matchday!O9="","",Matchday!O9) -> H | AW7: BET | AX7: 5 | AY7: A | AZ7: =IF(AW7="",AH7,AW7) -> BET | BA7: =IF(AX7<>"",AX7,IF(AH7<>"BET",0,IF(AI7*Method!$B$10/100<Method!$B$9,0,ROUND(AI7*Method!$B$10/100,0)))) -> 5 | BB7: 0 | BC7: 0.43491952 | BD7: 0.29039564 | BE7: 0.26176671 | BG7: 7 | BH7: warm_humid | BI7: 0
A8: 7 | B8: 46186 | C8: C | D8: Haiti | E8: Scotland | F8: Foxborough | G8: 21:00 | H8: 02:00 +1d | I8: 0.20669861 | J8: 0.26588249 | K8: 0.5274189 | L8: =IF(Matchday!E10="","",Matchday!E10) -> 6 | M8: =IF(Matchday!F10="","",Matchday!F10) -> 4.5 | N8: =IF(Matchday!G10="","",Matchday!G10) -> 0.53 | O8: =IF(L8="","",1/L8) -> 0.16666667 | P8: =IF(M8="","",1/M8) -> 0.22222222 | Q8: =IF(N8="","",1/N8) -> 1.8867925 | R8: =IF(COUNT(L8:N8)<3,"",O8+P8+Q8) -> 2.2756813 | S8: {=IF($R8="","",IF(Method!$B$56="proportional",O8/$R8,IF(Method!$B$56="power",IFERROR(INDEX(power_devig($L8,$M8,$N8),1,1),O8/$R8),IFERROR(INDEX(shin($L8,$M8,$N8),1,1),O8/$R8))))} -> 0.073238139 | T8: {=IF($R8="","",IF(Method!$B$56="proportional",P8/$R8,IF(Method!$B$56="power",IFERROR(INDEX(power_devig($L8,$M8,$N8),2,1),P8/$R8),IFERROR(INDEX(shin($L8,$M8,$N8),2,1),P8/$R8))))} -> 0.097650852 | U8: {=IF($R8="","",IF(Method!$B$56="proportional",Q8/$R8,IF(Method!$B$56="power",IFERROR(INDEX(power_devig($L8,$M8,$N8),3,1),Q8/$R8),IFERROR(INDEX(shin($L8,$M8,$N8),3,1),Q8/$R8))))} -> 0.82911101 | V8: =IF(S8="","",Method!$B$4*I8+(1-Method!$B$4)*S8/($S8+$T8+$U8)) -> 0.1199493 | W8: =IF(T8="","",Method!$B$4*J8+(1-Method!$B$4)*T8/($S8+$T8+$U8)) -> 0.15653193 | X8: =IF(U8="","",Method!$B$4*K8+(1-Method!$B$4)*U8/($S8+$T8+$U8)) -> 0.72351877 | Y8: =IF(V8="","",V8*L8-1) -> -0.28030418 | Z8: =IF(W8="","",W8*M8-1) -> -0.29560633 | AA8: =IF(X8="","",X8*N8-1) -> -0.61653505 | AB8: =IF(Y8="","",MATCH(MAX(Y8:AA8),Y8:AA8,0)) -> 1 | AC8: =IF(AB8="","",CHOOSE(AB8,"H","D","A")) -> H | AD8: =IF(AB8="","",CHOOSE(AB8,"1 "&D8,"X Draw","2 "&E8)) -> 1 Haiti | AE8: =IF(AB8="","",INDEX(L8:N8,1,AB8)) -> 6 | AF8: =IF(AB8="","",INDEX(Y8:AA8,1,AB8)) -> -0.28030418 | AG8: =IF(AB8="","",INDEX(V8:X8,1,AB8)-INDEX(S8:U8,1,AB8)) -> 0.046711164 | AH8: =IF(AB8="","· enter odds",IF(AND(AF8>=Method!$B$7,AG8>=Method!$B$8),"BET","PASS")) -> PASS | AI8: =IF(AH8<>"BET",0,ROUND(MIN(Method!$B$6,Method!$B$5*AL8)*100,1)) -> 0 | AJ8: =IF(OR(AH8<>"BET",Method!$B$55=TRUE()),0,IF(AI8*Method!$B$10/100<Method!$B$9,0,ROUND(AI8*Method!$B$10/100,0))) -> 0 | AK8: =IF(AB8="","",INDEX(V8:X8,1,AB8)) -> 0.1199493 | AL8: =IF(AH8<>"BET","",MAX(0,(AK8*AE8-1)/(AE8-1))) | AM8: =IF(AH8="BET",AF8+A8/1000000,"") | AN8: =IF(Matchday!N10="","",Matchday!N10) -> N | AO8: =IF(Matchday!P10="","",Matchday!P10) | AP8: =IF(Matchday!Q10="","",Matchday!Q10) | AQ8: =IF(Matchday!R10="","",Matchday!R10) | AR8: =IF(OR(AN8<>"Y",AQ8="",AV8=""),"",IF(AQ8="Void",0,IF(AQ8=AV8,ROUND(AP8*(AO8-1),2),-AP8))) | AS8: =IF(AR8="","",SUM($AR$2:AR8)) | AT8: =IF(AB8="","Type the 3 odds on the Matchday tab",IF(Method!$B$55=TRUE(),"🛑 PAUSED — drawdown "&TEXT(Method!$B$51,"0.0%")&" ≥ "&TEXT(Method!$B$52,"0.0%")&". Set Method!B54=Y to override.",IF(AH8="BET",IF(AJ8=0,"Edge found but stake rounds under £"&Method!$B$9&" — skip","Value found: EV "&TEXT(AF8,"0.0%")&", edge "&TEXT(AG8,"0.0%")),IF(AF8<Method!$B$7,"Price too short — EV "&TEXT(AF8,"0.0%")&" (need "&TEXT(Method!$B$7,"0.0%")&"+)","Model ≈ market — edge "&TEXT(AG8,"0.0%")&" (need "&TEXT(Method!$B$8,"0.0%")&"+)")))) -> 🛑 PAUSED — drawdown 0.6% ≥ 15.0%. Set Method!B54=Y to override. | AU8: =IF(AN8<>"Y","",IF(AH8="· enter odds","⚠ type the 3 odds (1/X/2) to grade this bet",IF(OR(AV8="",AO8="",AP8=""),"⚠ log backed pick, odds & stake",IF(AZ8<>"BET","⚠ FUN BET — engine said pass · staked £"&AP8&" vs engine £"&BA8,IF(AV8<>IF(AY8="",AC8,AY8),"⚠ backed "&AV8&" but engine pick was "&IF(AY8="",AC8,AY8),IF(AP8>BA8,"⚠ stake over engine £"&BA8,IF(ABS(AO8-IFERROR(INDEX(L8:N8,1,MATCH(AV8,{"H","D","A"},0)),AE8))>0.02,"⚠ odds moved — re-check value","✓ engine bet"))))))) | AV8: =IF(Matchday!O10="","",Matchday!O10) | AZ8: =IF(AW8="",AH8,AW8) -> PASS | BA8: =IF(AX8<>"",AX8,IF(AH8<>"BET",0,IF(AI8*Method!$B$10/100<Method!$B$9,0,ROUND(AI8*Method!$B$10/100,0)))) -> 0 | BB8: 0 | BC8: 0.18941496 | BD8: 0.28076171 | BE8: 0.51170651 | BG8: 40 | BH8: warm | BI8: 0
A9: 8 | B9: 46186 | C9: D | D9: Australia | E9: Turkey | F9: Vancouver | G9: 21:00 | H9: 05:00 +1d | I9: 0.3613933 | J9: 0.30639872 | K9: 0.33220798 | L9: =IF(Matchday!E11="","",Matchday!E11) -> 5.25 | M9: =IF(Matchday!F11="","",Matchday!F11) -> 3.8 | N9: =IF(Matchday!G11="","",Matchday!G11) -> 1.66 | O9: =IF(L9="","",1/L9) -> 0.19047619 | P9: =IF(M9="","",1/M9) -> 0.26315789 | Q9: =IF(N9="","",1/N9) -> 0.60240964 | R9: =IF(COUNT(L9:N9)<3,"",O9+P9+Q9) -> 1.0560437 | S9: {=IF($R9="","",IF(Method!$B$56="proportional",O9/$R9,IF(Method!$B$56="power",IFERROR(INDEX(power_devig($L9,$M9,$N9),1,1),O9/$R9),IFERROR(INDEX(shin($L9,$M9,$N9),1,1),O9/$R9))))} -> 0.17404997 | T9: {=IF($R9="","",IF(Method!$B$56="proportional",P9/$R9,IF(Method!$B$56="power",IFERROR(INDEX(power_devig($L9,$M9,$N9),2,1),P9/$R9),IFERROR(INDEX(shin($L9,$M9,$N9),2,1),P9/$R9))))} -> 0.24564306 | U9: {=IF($R9="","",IF(Method!$B$56="proportional",Q9/$R9,IF(Method!$B$56="power",IFERROR(INDEX(power_devig($L9,$M9,$N9),3,1),Q9/$R9),IFERROR(INDEX(shin($L9,$M9,$N9),3,1),Q9/$R9))))} -> 0.58030697 | V9: =IF(S9="","",Method!$B$4*I9+(1-Method!$B$4)*S9/($S9+$T9+$U9)) -> 0.23962014 | W9: =IF(T9="","",Method!$B$4*J9+(1-Method!$B$4)*T9/($S9+$T9+$U9)) -> 0.26690754 | X9: =IF(U9="","",Method!$B$4*K9+(1-Method!$B$4)*U9/($S9+$T9+$U9)) -> 0.49347232 | Y9: =IF(V9="","",V9*L9-1) -> 0.25800572 | Z9: =IF(W9="","",W9*M9-1) -> 0.014248645 | AA9: =IF(X9="","",X9*N9-1) -> -0.18083594 | AB9: =IF(Y9="","",MATCH(MAX(Y9:AA9),Y9:AA9,0)) -> 1 | AC9: =IF(AB9="","",CHOOSE(AB9,"H","D","A")) -> H | AD9: =IF(AB9="","",CHOOSE(AB9,"1 "&D9,"X Draw","2 "&E9)) -> 1 Australia | AE9: =IF(AB9="","",INDEX(L9:N9,1,AB9)) -> 5.25 | AF9: =IF(AB9="","",INDEX(Y9:AA9,1,AB9)) -> 0.25800572 | AG9: =IF(AB9="","",INDEX(V9:X9,1,AB9)-INDEX(S9:U9,1,AB9)) -> 0.065570164 | AH9: =IF(AB9="","· enter odds",IF(AND(AF9>=Method!$B$7,AG9>=Method!$B$8),"BET","PASS")) -> BET | AI9: =IF(AH9<>"BET",0,ROUND(MIN(Method!$B$6,Method!$B$5*AL9)*100,1)) -> 1.5 | AJ9: =IF(OR(AH9<>"BET",Method!$B$55=TRUE()),0,IF(AI9*Method!$B$10/100<Method!$B$9,0,ROUND(AI9*Method!$B$10/100,0))) -> 0 | AK9: =IF(AB9="","",INDEX(V9:X9,1,AB9)) -> 0.23962014 | AL9: =IF(AH9<>"BET","",MAX(0,(AK9*AE9-1)/(AE9-1))) -> 0.060707229 | AM9: =IF(AH9="BET",AF9+A9/1000000,"") -> 0.25801372 | AN9: =IF(Matchday!N11="","",Matchday!N11) -> Y | AO9: =IF(Matchday!P11="","",Matchday!P11) -> 5.25 | AP9: =IF(Matchday!Q11="","",Matchday!Q11) -> 10 | AQ9: =IF(Matchday!R11="","",Matchday!R11) -> H | AR9: =IF(OR(AN9<>"Y",AQ9="",AV9=""),"",IF(AQ9="Void",0,IF(AQ9=AV9,ROUND(AP9*(AO9-1),2),-AP9))) -> 42.5 | AS9: =IF(AR9="","",SUM($AR$2:AR9)) -> 64.3 | AT9: =IF(AB9="","Type the 3 odds on the Matchday tab",IF(Method!$B$55=TRUE(),"🛑 PAUSED — drawdown "&TEXT(Method!$B$51,"0.0%")&" ≥ "&TEXT(Method!$B$52,"0.0%")&". Set Method!B54=Y to override.",IF(AH9="BET",IF(AJ9=0,"Edge found but stake rounds under £"&Method!$B$9&" — skip","Value found: EV "&TEXT(AF9,"0.0%")&", edge "&TEXT(AG9,"0.0%")),IF(AF9<Method!$B$7,"Price too short — EV "&TEXT(AF9,"0.0%")&" (need "&TEXT(Method!$B$7,"0.0%")&"+)","Model ≈ market — edge "&TEXT(AG9,"0.0%")&" (need "&TEXT(Method!$B$8,"0.0%")&"+)")))) -> 🛑 PAUSED — drawdown 0.6% ≥ 15.0%. Set Method!B54=Y to override. | AU9: =IF(AN9<>"Y","",IF(AH9="· enter odds","⚠ type the 3 odds (1/X/2) to grade this bet",IF(OR(AV9="",AO9="",AP9=""),"⚠ log backed pick, odds & stake",IF(AZ9<>"BET","⚠ FUN BET — engine said pass · staked £"&AP9&" vs engine £"&BA9,IF(AV9<>IF(AY9="",AC9,AY9),"⚠ backed "&AV9&" but engine pick was "&IF(AY9="",AC9,AY9),IF(AP9>BA9,"⚠ stake over engine £"&BA9,IF(ABS(AO9-IFERROR(INDEX(L9:N9,1,MATCH(AV9,{"H","D","A"},0)),AE9))>0.02,"⚠ odds moved — re-check value","✓ engine bet"))))))) -> ⚠ stake over engine £0 | AV9: =IF(Matchday!O11="","",Matchday!O11) -> H | AW9: BET | AX9: 0 | AY9: H | AZ9: =IF(AW9="",AH9,AW9) -> BET | BA9: =IF(AX9<>"",AX9,IF(AH9<>"BET",0,IF(AI9*Method!$B$10/100<Method!$B$9,0,ROUND(AI9*Method!$B$10/100,0)))) -> 0 | BB9: 0 | BC9: 0.3514023 | BD9: 0.29608015 | BE9: 0.34252063 | BG9: 0 | BH9: mild_indoor | BI9: 0
A10: 9 | B10: 46187 | C10: E | D10: Germany | E10: Curacao | F10: Houston | G10: 12:00 | H10: 18:00 | I10: 0.73873705 | J10: 0.17963937 | K10: 0.081623574 | L10: =IF(Matchday!E12="","",Matchday!E12) -> 1.03 | M10: =IF(Matchday!F12="","",Matchday!F12) -> 19 | N10: =IF(Matchday!G12="","",Matchday!G12) -> 34 | O10: =IF(L10="","",1/L10) -> 0.97087379 | P10: =IF(M10="","",1/M10) -> 0.052631579 | Q10: =IF(N10="","",1/N10) -> 0.029411765 | R10: =IF(COUNT(L10:N10)<3,"",O10+P10+Q10) -> 1.0529171 | S10: {=IF($R10="","",IF(Method!$B$56="proportional",O10/$R10,IF(Method!$B$56="power",IFERROR(INDEX(power_devig($L10,$M10,$N10),1,1),O10/$R10),IFERROR(INDEX(shin($L10,$M10,$N10),1,1),O10/$R10))))} -> 0.94526903 | T10: {=IF($R10="","",IF(Method!$B$56="proportional",P10/$R10,IF(Method!$B$56="power",IFERROR(INDEX(power_devig($L10,$M10,$N10),2,1),P10/$R10),IFERROR(INDEX(shin($L10,$M10,$N10),2,1),P10/$R10))))} -> 0.037933235 | U10: {=IF($R10="","",IF(Method!$B$56="proportional",Q10/$R10,IF(Method!$B$56="power",IFERROR(INDEX(power_devig($L10,$M10,$N10),3,1),Q10/$R10),IFERROR(INDEX(shin($L10,$M10,$N10),3,1),Q10/$R10))))} -> 0.016797735 | V10: =IF(S10="","",Method!$B$4*I10+(1-Method!$B$4)*S10/($S10+$T10+$U10)) -> 0.87298284 | W10: =IF(T10="","",Method!$B$4*J10+(1-Method!$B$4)*T10/($S10+$T10+$U10)) -> 0.087530383 | X10: =IF(U10="","",Method!$B$4*K10+(1-Method!$B$4)*U10/($S10+$T10+$U10)) -> 0.039486779 | Y10: =IF(V10="","",V10*L10-1) -> -0.10082768 | Z10: =IF(W10="","",W10*M10-1) -> 0.66307727 | AA10: =IF(X10="","",X10*N10-1) -> 0.34255048 | AB10: =IF(Y10="","",MATCH(MAX(Y10:AA10),Y10:AA10,0)) -> 2 | AC10: =IF(AB10="","",CHOOSE(AB10,"H","D","A")) -> D | AD10: =IF(AB10="","",CHOOSE(AB10,"1 "&D10,"X Draw","2 "&E10)) -> X Draw | AE10: =IF(AB10="","",INDEX(L10:N10,1,AB10)) -> 19 | AF10: =IF(AB10="","",INDEX(Y10:AA10,1,AB10)) -> 0.66307727 | AG10: =IF(AB10="","",INDEX(V10:X10,1,AB10)-INDEX(S10:U10,1,AB10)) -> 0.049597147 | AH10: =IF(AB10="","· enter odds",IF(AND(AF10>=Method!$B$7,AG10>=Method!$B$8),"BET","PASS")) -> BET | AI10: =IF(AH10<>"BET",0,ROUND(MIN(Method!$B$6,Method!$B$5*AL10)*100,1)) -> 0.9 | AJ10: =IF(OR(AH10<>"BET",Method!$B$55=TRUE()),0,IF(AI10*Method!$B$10/100<Method!$B$9,0,ROUND(AI10*Method!$B$10/100,0))) -> 0 | AK10: =IF(AB10="","",INDEX(V10:X10,1,AB10)) -> 0.087530383 | AL10: =IF(AH10<>"BET","",MAX(0,(AK10*AE10-1)/(AE10-1))) -> 0.036837626 | AM10: =IF(AH10="BET",AF10+A10/1000000,"") -> 0.66308627 | AN10: =IF(Matchday!N12="","",Matchday!N12) -> Y | AO10: =IF(Matchday!P12="","",Matchday!P12) -> 19 | AP10: =IF(Matchday!Q12="","",Matchday!Q12) -> 6 | AQ10: =IF(Matchday!R12="","",Matchday!R12) -> H | AR10: =IF(OR(AN10<>"Y",AQ10="",AV10=""),"",IF(AQ10="Void",0,IF(AQ10=AV10,ROUND(AP10*(AO10-1),2),-AP10))) -> -6 | AS10: =IF(AR10="","",SUM($AR$2:AR10)) -> 58.3 | AT10: =IF(AB10="","Type the 3 odds on the Matchday tab",IF(Method!$B$55=TRUE(),"🛑 PAUSED — drawdown "&TEXT(Method!$B$51,"0.0%")&" ≥ "&TEXT(Method!$B$52,"0.0%")&". Set Method!B54=Y to override.",IF(AH10="BET",IF(AJ10=0,"Edge found but stake rounds under £"&Method!$B$9&" — skip","Value found: EV "&TEXT(AF10,"0.0%")&", edge "&TEXT(AG10,"0.0%")),IF(AF10<Method!$B$7,"Price too short — EV "&TEXT(AF10,"0.0%")&" (need "&TEXT(Method!$B$7,"0.0%")&"+)","Model ≈ market — edge "&TEXT(AG10,"0.0%")&" (need "&TEXT(Method!$B$8,"0.0%")&"+)")))) -> 🛑 PAUSED — drawdown 0.6% ≥ 15.0%. Set Method!B54=Y to override. | AU10: =IF(AN10<>"Y","",IF(AH10="· enter odds","⚠ type the 3 odds (1/X/2) to grade this bet",IF(OR(AV10="",AO10="",AP10=""),"⚠ log backed pick, odds & stake",IF(AZ10<>"BET","⚠ FUN BET — engine said pass · staked £"&AP10&" vs engine £"&BA10,IF(AV10<>IF(AY10="",AC10,AY10),"⚠ backed "&AV10&" but engine pick was "&IF(AY10="",AC10,AY10),IF(AP10>BA10,"⚠ stake over engine £"&BA10,IF(ABS(AO10-IFERROR(INDEX(L10:N10,1,MATCH(AV10,{"H","D","A"},0)),AE10))>0.02,"⚠ odds moved — re-check value","✓ engine bet"))))))) -> ✓ engine bet | AV10: =IF(Matchday!O12="","",Matchday!O12) -> D | AW10: BET | AX10: 6 | AY10: D | AZ10: =IF(AW10="",AH10,AW10) -> BET | BA10: =IF(AX10<>"",AX10,IF(AH10<>"BET",0,IF(AI10*Method!$B$10/100<Method!$B$9,0,ROUND(AI10*Method!$B$10/100,0)))) -> 6 | BB10: 0 | BC10: 0.69015642 | BD10: 0.20403639 | BE10: 0.082269221 | BG10: 15 | BH10: very_hot_humid_indoor | BI10: 0
