Workbook

Sheet READ ME
A2: READ ME — 1 MINUTE
A3: The ONLY tab you use is MATCHDAY. (Bets = engine audit · Dashboard = scoreboard · Method = settings & rules · Model vs Market = context.)
A5: YELLOW CELLS = YOU TYPE. There are only 5 things, all on the Matchday tab:
A6: 1. Odds 1 / X / 2 — the three DECIMAL prices from your betting app (1 = home, X = draw, 2 = away). 21/50 → 1.42 · 7/2 → 4.50 · 15/2 → 8.50. Bet365: Settings → Odds format → Decimal.
A7: 2. Team news OK? — Y or N. Only needed when DECISION says BET.
A8: 3. Placed? + Backed (H/D/A) + Odds you got + Stake you placed — your log AFTER you bet. "Backed" = the outcome on your slip; P&L grades against it, so model updates can never rewrite your record.
A9: 4. Result — H, D, A or Void, after full time.
A10: 5. Closing odds (optional) — the price just before kickoff, for the CLV homework.
A12: EVERYTHING ELSE IS AUTOMATIC: PICK, DECISION, ENGINE STAKE, WHY, FINAL ACTION, STATUS, CLV, the whole Dashboard and your bankroll.
A14: HOW TO READ THE ANSWER
A15: · ENGINE STAKE "–" + FINAL ACTION "❌ NO BET" → the engine DID respond: do not bet this match. Example: South Korea v Czechia at 2.70 / 3.10 / 2.80 → EV +1.6%, below the 2.5% bar → NO BET. Nothing is broken.
A16: · FINAL ACTION "🟢 PLACE £x on [pick]" → bet exactly that amount on exactly that pick, after the team-news check.
... A32: v2.2 — last-mile hardening: pause can no longer distort the STATUS text for un-snapshotted bets; First-time setup now retro-snapshots any bet placed before the script existed; snapshot cells stay writable for shared editors (share view-only with friends regardless — they scale stakes via "£ / £100 bank").

Sheet Goal Grid
A1: GOAL GRID — fair P for O/U, BTTS, AH from λ_h/λ_a · Poisson + Dixon-Coles τ=-0.13 · MAX_GOALS=15 · ⚠ DRIFT: Poisson vs prod NB+DC ≈2-9pp on OU2.5/BTTS; BET? uses Method!B8 edge threshold (raise B8 to 0.08 for an 8pp drift buffer)
A2: Source: /predictions_live.json · match_predictions[] · type Over 2.5 book odds in K for BET? signal
A3: #m | B3: Date | C3: Home | D3: Away | E3: λ_home | F3: λ_away | G3: Fair O/U 2.5 | H3: Fair BTTS | I3: Fair O/U 1.5 | J3: Fair O/U 3.5 | K3: Book O 2.5 | L3: Book U 2.5 | M3: Book BTTS Y | N3: Implied O 2.5 | O3: Edge % | P3: BET?
A4: 1 | B4: 46184 | C4: Mexico | D4: South Africa | E4: 2.5240228 | F4: 0.49607706 | G4: =IFERROR(GOAL_GRID(E4,F4,"ou25"),"") -> 0.59686922 | H4: =IFERROR(GOAL_GRID(E4,F4,"btts"),"") -> 0.37753708 | I4: =IFERROR(GOAL_GRID(E4,F4,"ou15"),"") -> 0.83352165 | J4: =IFERROR(GOAL_GRID(E4,F4,"ou35"),"") -> 0.36684143 | N4: =IF(K4="","",1/K4) | O4: =IF(OR(G4="",N4=""),"",G4-N4) | P4: =IF(Method!$B$55=TRUE(),"🛑 PAUSED",IF(O4="","",IF(O4<Method!$B$8,"PASS","BET")))
A5: 2 | B5: 46184 | C5: South Korea | D5: Czechia | E5: 1.4271605 | F5: 1.0216546 | G5: =IFERROR(GOAL_GRID(E5,F5,"ou25"),"") -> 0.44381124 | H5: =IFERROR(GOAL_GRID(E5,F5,"btts"),"") -> 0.50371419 | I5: =IFERROR(GOAL_GRID(E5,F5,"ou15"),"") -> 0.71974199 | J5: =IFERROR(GOAL_GRID(E5,F5,"ou35"),"") -> 0.23196895 | N5: =IF(K5="","",1/K5) | O5: =IF(OR(G5="",N5=""),"",G5-N5) | P5: =IF(Method!$B$55=TRUE(),"🛑 PAUSED",IF(O5="","",IF(O5<Method!$B$8,"PASS","BET")))
A6: 3 | B6: 46185 | C6: Canada | D6: Bosnia and Herzegovina | E6: 2.2224662 | F6: 0.52223951 | G6: =IFERROR(GOAL_GRID(E6,F6,"ou25"),"") -> 0.53006453 | H6: =IFERROR(GOAL_GRID(E6,F6,"btts"),"") -> 0.38164948 | I6: =IFERROR(GOAL_GRID(E6,F6,"ou15"),"") -> 0.78806835 | J6: =IFERROR(GOAL_GRID(E6,F6,"ou35"),"") -> 0.30310771 | N6: =IF(K6="","",1/K6) | O6: =IF(OR(G6="",N6=""),"",G6-N6) | P6: =IF(Method!$B$55=TRUE(),"🛑 PAUSED",IF(O6="","",IF(O6<Method!$B$8,"PASS","BET")))
A7: 4 | B7: 46185 | C7: United States | D7: Paraguay | E7: 1.5587058 | F7: 0.95105469 | G7: =IFERROR(GOAL_GRID(E7,F7,"ou25"),"") -> 0.46048492 | H7: =IFERROR(GOAL_GRID(E7,F7,"btts"),"") -> 0.50217085 | I7: =IFERROR(GOAL_GRID(E7,F7,"ou15"),"") -> 0.73322587 | J7: =IFERROR(GOAL_GRID(E7,F7,"ou35"),"") -> 0.24547012 | N7: =IF(K7="","",1/K7) | O7: =IF(OR(G7="",N7=""),"",G7-N7) | P7: =IF(Method!$B$55=TRUE(),"🛑 PAUSED",IF(O7="","",IF(O7<Method!$B$8,"PASS","BET")))
A8: 5 | B8: 46186 | C8: Qatar | D8: Switzerland | E8: 0.46476638 | F8: 2.7748048 | G8: =IFERROR(GOAL_GRID(E8,F8,"ou25"),"") -> 0.64584779 | H8: =IFERROR(GOAL_GRID(E8,F8,"btts"),"") -> 0.36502748 | I8: =IFERROR(GOAL_GRID(E8,F8,"ou15"),"") -> 0.86394158 | J8: =IFERROR(GOAL_GRID(E8,F8,"ou35"),"") -> 0.41762916 | N8: =IF(K8="","",1/K8) | O8: =IF(OR(G8="",N8=""),"",G8-N8) | P8: =IF(Method!$B$55=TRUE(),"🛑 PAUSED",IF(O8="","",IF(O8<Method!$B$8,"PASS","BET")))
A9: 6 | B9: 46186 | C9: Brazil | D9: Morocco | E9: 1.3950821 | F9: 1.1852653 | G9: =IFERROR(GOAL_GRID(E9,F9,"ou25"),"") -> 0.47683235 | H9: =IFERROR(GOAL_GRID(E9,F9,"btts"),"") -> 0.53878625 | I9: =IFERROR(GOAL_GRID(E9,F9,"ou15"),"") -> 0.74540287 | J9: =IFERROR(GOAL_GRID(E9,F9,"ou35"),"") -> 0.25984173 | N9: =IF(K9="","",1/K9) | O9: =IF(OR(G9="",N9=""),"",G9-N9) | P9: =IF(Method!$B$55=TRUE(),"🛑 PAUSED",IF(O9="","",IF(O9<Method!$B$8,"PASS","BET")))
A10: 7 | B10: 46186 | C10: Haiti | D10: Scotland | E10: 0.9333598 | F10: 1.7620295 | G10: =IFERROR(GOAL_GRID(E10,F10,"ou25"),"") -> 0.50830905 | H10: =IFERROR(GOAL_GRID(E10,F10,"btts"),"") -> 0.52015969 | I10: =IFERROR(GOAL_GRID(E10,F10,"ou15"),"") -> 0.76957499 | J10: =IFERROR(GOAL_GRID(E10,F10,"ou35"),"") -> 0.28661908 | N10: =IF(K10="","",1/K10) | O10: =IF(OR(G10="",N10=""),"",G10-N10) | P10: =IF(Method!$B$55=TRUE(),"🛑 PAUSED",IF(O10="","",IF(O10<Method!$B$8,"PASS","BET")))
A11: 8 | B11: 46186 | C11: Australia | D11: Turkey | E11: 1.0624391 | F11: 1.1295289 | G11: =IFERROR(GOAL_GRID(E11,F11,"ou25"),"") -> 0.37515625 | H11: =IFERROR(GOAL_GRID(E11,F11,"btts"),"") -> 0.46035502 | I11: =IFERROR(GOAL_GRID(E11,F11,"ou15"),"") -> 0.66093635 | J11: =IFERROR(GOAL_GRID(E11,F11,"ou35"),"") -> 0.17908219 | N11: =IF(K11="","",1/K11) | O11: =IF(OR(G11="",N11=""),"",G11-N11) | P11: =IF(Method!$B$55=TRUE(),"🛑 PAUSED",IF(O11="","",IF(O11<Method!$B$8,"PASS","BET")))
A12: 9 | B12: 46187 | C12: Germany | D12: Curacao | E12: 2.9122472 | F12: 0.61247241 | G12: =IFERROR(GOAL_GRID(E12,F12,"ou25"),"") -> 0.69783585 | H12: =IFERROR(GOAL_GRID(E12,F12,"btts"),"") -> 0.4490239 | I12: =IFERROR(GOAL_GRID(E12,F12,"ou15"),"") -> 0.89159241 | J12: =IFERROR(GOAL_GRID(E12,F12,"ou35"),"") -> 0.47838185 | N12: =IF(K12="","",1/K12) | O12: =IF(OR(G12="",N12=""),"",G12-N12) | P12: =IF(Method!$B$55=TRUE(),"🛑 PAUSED",IF(O12="","",IF(O12<Method!$B$8,"PASS","BET")))
A13: 10 | B13: 46187 | C13: Netherlands | D13: Japan | E13: 1.5585992 | F13: 0.96455956 | G13: =IFERROR(GOAL_GRID(E13,F13,"ou25"),"") -> 0.46382016 | H13: =IFERROR(GOAL_GRID(E13,F13,"btts"),"") -> 0.50616176 | I13: =IFERROR(GOAL_GRID(E13,F13,"ou15"),"") -> 0.73580458 | J13: =IFERROR(GOAL_GRID(E13,F13,"ou35"),"") -> 0.24829923 | N13: =IF(K13="","",1/K13) | O13: =IF(OR(G13="",N13=""),"",G13-N13) | P13: =IF(Method!$B$55=TRUE(),"🛑 PAUSED",IF(O13="","",IF(O13<Method!$B$8,"PASS","BET")))
A14: 11 | B14: 46187 | C14: Ivory Coast | D14: Ecuador | E14: 0.92886335 | F14: 1.5627021 | G14: =IFERROR(GOAL_GRID(E14,F14,"ou25"),"") -> 0.45599291 | H14: =IFERROR(GOAL_GRID(E14,F14,"btts"),"") -> 0.49597373 | I14: =IFERROR(GOAL_GRID(E14,F14,"ou15"),"") -> 0.72974284 | J14: =IFERROR(GOAL_GRID(E14,F14,"ou35"),"") -> 0.24166722 | N14: =IF(K14="","",1/K14) | O14: =IF(OR(G14="",N14=""),"",G14-N14) | P14: =IF(Method!$B$55=TRUE(),"🛑 PAUSED",IF(O14="","",IF(O14<Method!$B$8,"PASS","BET")))
A15: 12 | B15: 46187 | C15: Sweden | D15: Tunisia | E15: 1.4041743 | F15: 1.1511817 | G15: =IFERROR(GOAL_GRID(E15,F15,"ou25"),"") -> 0.4706101 | H15: =IFERROR(GOAL_GRID(E15,F15,"btts"),"") -> 0.53249655 | I15: =IFERROR(GOAL_GRID(E15,F15,"ou15"),"") -> 0.74067384 | J15: =IFERROR(GOAL_GRID(E15,F15,"ou35"),"") -> 0.25448424 | N15: =IF(K15="","",1/K15) | O15: =IF(OR(G15="",N15=""),"",G15-N15) | P15: =IF(Method!$B$55=TRUE(),"🛑 PAUSED",IF(O15="","",IF(O15<Method!$B$8,"PASS","BET")))
... A103: 100 | B103: 46214 | C103: Argentina | D103: Switzerland | E103: 2.0778609 | F103: 0.53434993 | G103: =IFERROR(GOAL_GRID(E103,F103,"ou25"),"") -> 0.49590064 | H103: =IFERROR(GOAL_GRID(E103,F103,"btts"),"") -> 0.38138148 | I103: =IFERROR(GOAL_GRID(E103,F103,"ou15"),"") -> 0.76289114 | J103: =IFERROR(GOAL_GRID(E103,F103,"ou35"),"") -> 0.27285812 | N103: =IF(K103="","",1/K103) | O103: =IF(OR(G103="",N103=""),"",G103-N103) | P103: =IF(Method!$B$55=TRUE(),"🛑 PAUSED",IF(O103="","",IF(O103<Method!$B$8,"PASS","BET")))
A104: 101 | B104: 46217 | C104: W97 | D104: W98
A105: 102 | B105: 46218 | C105: W99 | D105: W100
A106: 103 | B106: 46221 | C106: L101 | D106: L102
A107: 104 | B107: 46222 | C107: W101 | D107: W102

Sheet CLV
A1: CLV — closing-line-value tracker · rolling 20-bet average · positive CLV = beating the close | B1: CLV tracked for 1X2 picks only — O/U and BTTS coming in v2.4
A2: Source: Bets!AO backed odds + AW:AY snapshot block · type closing odds in col F after market closes
A3: Bet # | B3: #m | C3: Pick | D3: Stake | E3: Taken odds | F3: Closing odds | G3: CLV % | H3: Rolling 20 CLV % | I3: Status
A4: 1 | B4: 2 | C4: H | D4: 3 | E4: 2.6 | G4: =IF(OR(E4="",F4="",NOT(ISNUMBER(E4)),NOT(ISNUMBER(F4)),E4<=0,F4<=0),"",(E4-F4)/F4) | H4: =IFERROR(IF(COUNT(G4)<20,"n="&COUNT(G4)&": "&AVERAGE(G4),AVERAGE(G4)),"") | I4: =IFERROR(__xludf.DUMMYFUNCTION("IF(H4="""","""",IF(ISNUMBER(H4),IF(H4>0,""BEATING CLOSE"",""BELOW CLOSE""),IF(IFERROR(VALUE(REGEXEXTRACT(H4,"": (.*)$"")),0)>0,""BEATING CLOSE (n<20)"",""BELOW CLOSE (n<20)"")))"),"")
A5: 2 | B5: 3 | C5: H | D5: 12 | E5: 1.85 | G5: =IF(OR(E5="",F5="",NOT(ISNUMBER(E5)),NOT(ISNUMBER(F5)),E5<=0,F5<=0),"",(E5-F5)/F5) | H5: =IFERROR(IF(COUNT(G4:G5)<20,"n="&COUNT(G4:G5)&": "&AVERAGE(G4:G5),AVERAGE(G4:G5)),"") | I5: =IFERROR(__xludf.DUMMYFUNCTION("IF(H5="""","""",IF(ISNUMBER(H5),IF(H5>0,""BEATING CLOSE"",""BELOW CLOSE""),IF(IFERROR(VALUE(REGEXEXTRACT(H5,"": (.*)$"")),0)>0,""BEATING CLOSE (n<20)"",""BELOW CLOSE (n<20)"")))"),"")
A6: 3 | B6: 6 | C6: A | D6: 5 | E6: 1.68 | G6: =IF(OR(E6="",F6="",NOT(ISNUMBER(E6)),NOT(ISNUMBER(F6)),E6<=0,F6<=0),"",(E6-F6)/F6) | H6: =IFERROR(IF(COUNT(G4:G6)<20,"n="&COUNT(G4:G6)&": "&AVERAGE(G4:G6),AVERAGE(G4:G6)),"") | I6: =IFERROR(__xludf.DUMMYFUNCTION("IF(H6="""","""",IF(ISNUMBER(H6),IF(H6>0,""BEATING CLOSE"",""BELOW CLOSE""),IF(IFERROR(VALUE(REGEXEXTRACT(H6,"": (.*)$"")),0)>0,""BEATING CLOSE (n<20)"",""BELOW CLOSE (n<20)"")))"),"")
A7: 4 | B7: 8 | C7: H | D7: 0 | E7: 5.25 | G7: =IF(OR(E7="",F7="",NOT(ISNUMBER(E7)),NOT(ISNUMBER(F7)),E7<=0,F7<=0),"",(E7-F7)/F7) | H7: =IFERROR(IF(COUNT(G4:G7)<20,"n="&COUNT(G4:G7)&": "&AVERAGE(G4:G7),AVERAGE(G4:G7)),"") | I7: =IFERROR(__xludf.DUMMYFUNCTION("IF(H7="""","""",IF(ISNUMBER(H7),IF(H7>0,""BEATING CLOSE"",""BELOW CLOSE""),IF(IFERROR(VALUE(REGEXEXTRACT(H7,"": (.*)$"")),0)>0,""BEATING CLOSE (n<20)"",""BELOW CLOSE (n<20)"")))"),"")
A8: 5 | B8: 9 | C8: D | D8: 6 | E8: 19 | G8: =IF(OR(E8="",F8="",NOT(ISNUMBER(E8)),NOT(ISNUMBER(F8)),E8<=0,F8<=0),"",(E8-F8)/F8) | H8: =IFERROR(IF(COUNT(G4:G8)<20,"n="&COUNT(G4:G8)&": "&AVERAGE(G4:G8),AVERAGE(G4:G8)),"") | I8: =IFERROR(__xludf.DUMMYFUNCTION("IF(H8="""","""",IF(ISNUMBER(H8),IF(H8>0,""BEATING CLOSE"",""BELOW CLOSE""),IF(IFERROR(VALUE(REGEXEXTRACT(H8,"": (.*)$"")),0)>0,""BEATING CLOSE (n<20)"",""BELOW CLOSE (n<20)"")))"),"")
A9: 6 | B9: 51 | C9: H | D9: 12 | E9: 7.5 | G9: =IF(OR(E9="",F9="",NOT(ISNUMBER(E9)),NOT(ISNUMBER(F9)),E9<=0,F9<=0),"",(E9-F9)/F9) | H9: =IFERROR(IF(COUNT(G4:G9)<20,"n="&COUNT(G4:G9)&": "&AVERAGE(G4:G9),AVERAGE(G4:G9)),"") | I9: =IFERROR(__xludf.DUMMYFUNCTION("IF(H9="""","""",IF(ISNUMBER(H9),IF(H9>0,""BEATING CLOSE"",""BELOW CLOSE""),IF(IFERROR(VALUE(REGEXEXTRACT(H9,"": (.*)$"")),0)>0,""BEATING CLOSE (n<20)"",""BELOW CLOSE (n<20)"")))"),"")
A10: 7 | B10: 69 | C10: H | D10: 19 | E10: 4.2 | G10: =IF(OR(E10="",F10="",NOT(ISNUMBER(E10)),NOT(ISNUMBER(F10)),E10<=0,F10<=0),"",(E10-F10)/F10) | H10: =IFERROR(IF(COUNT(G4:G10)<20,"n="&COUNT(G4:G10)&": "&AVERAGE(G4:G10),AVERAGE(G4:G10)),"") | I10: =IFERROR(__xludf.DUMMYFUNCTION("IF(H10="""","""",IF(ISNUMBER(H10),IF(H10>0,""BEATING CLOSE"",""BELOW CLOSE""),IF(IFERROR(VALUE(REGEXEXTRACT(H10,"": (.*)$"")),0)>0,""BEATING CLOSE (n<20)"",""BELOW CLOSE (n<20)"")))"),"")
A11: 8 | B11: 70 | C11: A | D11: 16 | E11: 5 | G11: =IF(OR(E11="",F11="",NOT(ISNUMBER(E11)),NOT(ISNUMBER(F11)),E11<=0,F11<=0),"",(E11-F11)/F11) | H11: =IFERROR(IF(COUNT(G4:G11)<20,"n="&COUNT(G4:G11)&": "&AVERAGE(G4:G11),AVERAGE(G4:G11)),"") | I11: =IFERROR(__xludf.DUMMYFUNCTION("IF(H11="""","""",IF(ISNUMBER(H11),IF(H11>0,""BEATING CLOSE"",""BELOW CLOSE""),IF(IFERROR(VALUE(REGEXEXTRACT(H11,"": (.*)$"")),0)>0,""BEATING CLOSE (n<20)"",""BELOW CLOSE (n<20)"")))"),"")

Sheet Dashboard
A1: WC26 GROUP STAGE — VALUE BETTING DASHBOARD
A2: Model snapshot 2026-06-10 14:10 UTC · type odds on the MATCHDAY tab on game day · stakes auto-size from current bankroll
A4: Current bankroll | B4: =Method!B10 -> 969.4 | C4: Matches today | D4: =COUNTIF(Bets!B2:B105,TODAY()) -> 1 | E4: Engine bets placed | F4: =SUMPRODUCT(--(Bets!AN2:AN105="Y"),--(Bets!AZ2:AZ105="BET")) -> 8 | G4: =IF(F5=0,"","⚠ "&F5&" fun bet(s) logged — excluded from engine quality. Judge the engine on Engine P&L and ✓ rows only.") -> ⚠ 4 fun bet(s) logged — excluded from engine quality. Judge the engine on Engine P&L and ✓ rows only.
A5: Staked (placed) | B5: =SUMIF(Bets!AN2:AN105,"Y",Bets!AP2:AP105) -> 178.5 | C5: Next match day | D5: =IFERROR(SMALL(Bets!B2:B105,COUNTIF(Bets!B2:B105,"<"&TODAY())+1),"finished") -> 46212 | E5: Fun bets placed | F5: =SUMPRODUCT(--(Bets!AN2:AN105="Y"),--(Bets!AZ2:AZ105<>"BET")) -> 4
A6: Settled P&L | B6: =SUM(Bets!AR2:AR105) -> -30.6 | C6: BET signals live | D6: =COUNTIF(Bets!AH2:AH105,"BET") -> 41 | E6: Avg CLV (logged) | F6: =IFERROR(AVERAGE(Matchday!U4:U107),"–") -> 0.86505467
A7: ROI (settled) | B7: =IF(SUMPRODUCT(--(Bets!AN2:AN105="Y"),--(Bets!AQ2:AQ105<>""),Bets!AP2:AP105)=0,"–",B6/SUMPRODUCT(--(Bets!AN2:AN105="Y"),--(Bets!AQ2:AQ105<>""),Bets!AP2:AP105)) -> -0.17142857 | C7: PASS | D7: =COUNTIF(Bets!AH2:AH105,"PASS") -> 59 | E7: Engine P&L | F7: =SUMIF(Bets!AZ2:AZ105,"BET",Bets!AR2:AR105) -> -40
A8: Record W–L | B8: =COUNTIF(Bets!AR2:AR105,">0")&" – "&COUNTIF(Bets!AR2:AR105,"<0") -> 4 – 7 | C8: Awaiting odds | D8: =COUNTIF(Bets!AH2:AH105,"· enter odds") -> 4 | E8: Fun-bet P&L | F8: =SUMIFS(Bets!AR2:AR105,Bets!AN2:AN105,"Y",Bets!AZ2:AZ105,"<>BET") -> 9.4
A9: Open bets | B9: =SUMPRODUCT(--(Bets!AN2:AN105="Y"),--(Bets!AQ2:AQ105="")) -> 0 | C9: Sum of BET stakes | D9: =SUM(Bets!AJ2:AJ105) -> 459
A11: LIVE VALUE BOARD — top BET signals right now (fills as you enter odds)
A12: # | B12: Date | C12: Group | D12: Match | E12: Pick | F12: Odds | G12: EV | H12: Edge | I12: Stake £
A13: {=IFERROR(INDEX(Bets!$A$2:$A$105,MATCH(LARGE(Bets!$AM$2:$AM$105,1),Bets!$AM$2:$AM$105,0)),"")} -> 97 | B13: {=IFERROR(INDEX(Bets!$B$2:$B$105,MATCH(LARGE(Bets!$AM$2:$AM$105,1),Bets!$AM$2:$AM$105,0)),"")} -> 46212 | C13: {=IFERROR(INDEX(Bets!$C$2:$C$105,MATCH(LARGE(Bets!$AM$2:$AM$105,1),Bets!$AM$2:$AM$105,0)),"")} -> QF | D13: {=IFERROR(INDEX(Bets!$D$2:$D$105,MATCH(LARGE(Bets!$AM$2:$AM$105,1),Bets!$AM$2:$AM$105,0))&" v "&INDEX(Bets!$E$2:$E$105,MATCH(LARGE(Bets!$AM$2:$AM$105,1),Bets!$AM$2:$AM$105,0)),"")} -> France v Morocco | E13: {=IFERROR(INDEX(Bets!$AD$2:$AD$105,MATCH(LARGE(Bets!$AM$2:$AM$105,1),Bets!$AM$2:$AM$105,0)),"")} -> 2 Morocco | F13: {=IFERROR(INDEX(Bets!$AE$2:$AE$105,MATCH(LARGE(Bets!$AM$2:$AM$105,1),Bets!$AM$2:$AM$105,0)),"")} -> 6.5 | G13: {=IFERROR(INDEX(Bets!$AF$2:$AF$105,MATCH(LARGE(Bets!$AM$2:$AM$105,1),Bets!$AM$2:$AM$105,0)),"")} -> 0.29746604 | H13: {=IFERROR(INDEX(Bets!$AG$2:$AG$105,MATCH(LARGE(Bets!$AM$2:$AM$105,1),Bets!$AM$2:$AM$105,0)),"")} -> 0.059174952 | I13: {=IFERROR(INDEX(Bets!$AJ$2:$AJ$105,MATCH(LARGE(Bets!$AM$2:$AM$105,1),Bets!$AM$2:$AM$105,0)),"")} -> 14
A14: {=IFERROR(INDEX(Bets!$A$2:$A$105,MATCH(LARGE(Bets!$AM$2:$AM$105,2),Bets!$AM$2:$AM$105,0)),"")} -> 56 | B14: {=IFERROR(INDEX(Bets!$B$2:$B$105,MATCH(LARGE(Bets!$AM$2:$AM$105,2),Bets!$AM$2:$AM$105,0)),"")} -> 46198 | C14: {=IFERROR(INDEX(Bets!$C$2:$C$105,MATCH(LARGE(Bets!$AM$2:$AM$105,2),Bets!$AM$2:$AM$105,0)),"")} -> E | D14: {=IFERROR(INDEX(Bets!$D$2:$D$105,MATCH(LARGE(Bets!$AM$2:$AM$105,2),Bets!$AM$2:$AM$105,0))&" v "&INDEX(Bets!$E$2:$E$105,MATCH(LARGE(Bets!$AM$2:$AM$105,2),Bets!$AM$2:$AM$105,0)),"")} -> Curacao v Ivory Coast | E14: {=IFERROR(INDEX(Bets!$AD$2:$AD$105,MATCH(LARGE(Bets!$AM$2:$AM$105,2),Bets!$AM$2:$AM$105,0)),"")} -> X Draw | F14: {=IFERROR(INDEX(Bets!$AE$2:$AE$105,MATCH(LARGE(Bets!$AM$2:$AM$105,2),Bets!$AM$2:$AM$105,0)),"")} -> 7.5 | G14: {=IFERROR(INDEX(Bets!$AF$2:$AF$105,MATCH(LARGE(Bets!$AM$2:$AM$105,2),Bets!$AM$2:$AM$105,0)),"")} -> 0.27230886 | H14: {=IFERROR(INDEX(Bets!$AG$2:$AG$105,MATCH(LARGE(Bets!$AM$2:$AM$105,2),Bets!$AM$2:$AM$105,0)),"")} -> 0.052771394 | I14: {=IFERROR(INDEX(Bets!$AJ$2:$AJ$105,MATCH(LARGE(Bets!$AM$2:$AM$105,2),Bets!$AM$2:$AM$105,0)),"")} -> 10
A15: {=IFERROR(INDEX(Bets!$A$2:$A$105,MATCH(LARGE(Bets!$AM$2:$AM$105,3),Bets!$AM$2:$AM$105,0)),"")} -> 8 | B15: {=IFERROR(INDEX(Bets!$B$2:$B$105,MATCH(LARGE(Bets!$AM$2:$AM$105,3),Bets!$AM$2:$AM$105,0)),"")} -> 46186 | C15: {=IFERROR(INDEX(Bets!$C$2:$C$105,MATCH(LARGE(Bets!$AM$2:$AM$105,3),Bets!$AM$2:$AM$105,0)),"")} -> D | D15: {=IFERROR(INDEX(Bets!$D$2:$D$105,MATCH(LARGE(Bets!$AM$2:$AM$105,3),Bets!$AM$2:$AM$105,0))&" v "&INDEX(Bets!$E$2:$E$105,MATCH(LARGE(Bets!$AM$2:$AM$105,3),Bets!$AM$2:$AM$105,0)),"")} -> Australia v Turkey | E15: {=IFERROR(INDEX(Bets!$AD$2:$AD$105,MATCH(LARGE(Bets!$AM$2:$AM$105,3),Bets!$AM$2:$AM$105,0)),"")} -> 1 Australia | F15: {=IFERROR(INDEX(Bets!$AE$2:$AE$105,MATCH(LARGE(Bets!$AM$2:$AM$105,3),Bets!$AM$2:$AM$105,0)),"")} -> 5.25 | G15: {=IFERROR(INDEX(Bets!$AF$2:$AF$105,MATCH(LARGE(Bets!$AM$2:$AM$105,3),Bets!$AM$2:$AM$105,0)),"")} -> 0.26943859 | H15: {=IFERROR(INDEX(Bets!$AG$2:$AG$105,MATCH(LARGE(Bets!$AM$2:$AM$105,3),Bets!$AM$2:$AM$105,0)),"")} -> 0.067747853 | I15: {=IFERROR(INDEX(Bets!$AJ$2:$AJ$105,MATCH(LARGE(Bets!$AM$2:$AM$105,3),Bets!$AM$2:$AM$105,0)),"")} -> 16
A16: {=IFERROR(INDEX(Bets!$A$2:$A$105,MATCH(LARGE(Bets!$AM$2:$AM$105,4),Bets!$AM$2:$AM$105,0)),"")} -> 44 | B16: {=IFERROR(INDEX(Bets!$B$2:$B$105,MATCH(LARGE(Bets!$AM$2:$AM$105,4),Bets!$AM$2:$AM$105,0)),"")} -> 46195 | C16: {=IFERROR(INDEX(Bets!$C$2:$C$105,MATCH(LARGE(Bets!$AM$2:$AM$105,4),Bets!$AM$2:$AM$105,0)),"")} -> J | D16: {=IFERROR(INDEX(Bets!$D$2:$D$105,MATCH(LARGE(Bets!$AM$2:$AM$105,4),Bets!$AM$2:$AM$105,0))&" v "&INDEX(Bets!$E$2:$E$105,MATCH(LARGE(Bets!$AM$2:$AM$105,4),Bets!$AM$2:$AM$105,0)),"")} -> Jordan v Algeria | E16: {=IFERROR(INDEX(Bets!$AD$2:$AD$105,MATCH(LARGE(Bets!$AM$2:$AM$105,4),Bets!$AM$2:$AM$105,0)),"")} -> 1 Jordan | F16: {=IFERROR(INDEX(Bets!$AE$2:$AE$105,MATCH(LARGE(Bets!$AM$2:$AM$105,4),Bets!$AM$2:$AM$105,0)),"")} -> 7.5 | G16: {=IFERROR(INDEX(Bets!$AF$2:$AF$105,MATCH(LARGE(Bets!$AM$2:$AM$105,4),Bets!$AM$2:$AM$105,0)),"")} -> 0.26022035 | H16: {=IFERROR(INDEX(Bets!$AG$2:$AG$105,MATCH(LARGE(Bets!$AM$2:$AM$105,4),Bets!$AM$2:$AM$105,0)),"")} -> 0.054694802 | I16: {=IFERROR(INDEX(Bets!$AJ$2:$AJ$105,MATCH(LARGE(Bets!$AM$2:$AM$105,4),Bets!$AM$2:$AM$105,0)),"")} -> 10
A17: {=IFERROR(INDEX(Bets!$A$2:$A$105,MATCH(LARGE(Bets!$AM$2:$AM$105,5),Bets!$AM$2:$AM$105,0)),"")} -> 55 | B17: {=IFERROR(INDEX(Bets!$B$2:$B$105,MATCH(LARGE(Bets!$AM$2:$AM$105,5),Bets!$AM$2:$AM$105,0)),"")} -> 46198 | C17: {=IFERROR(INDEX(Bets!$C$2:$C$105,MATCH(LARGE(Bets!$AM$2:$AM$105,5),Bets!$AM$2:$AM$105,0)),"")} -> E | D17: {=IFERROR(INDEX(Bets!$D$2:$D$105,MATCH(LARGE(Bets!$AM$2:$AM$105,5),Bets!$AM$2:$AM$105,0))&" v "&INDEX(Bets!$E$2:$E$105,MATCH(LARGE(Bets!$AM$2:$AM$105,5),Bets!$AM$2:$AM$105,0)),"")} -> Ecuador v Germany | E17: {=IFERROR(INDEX(Bets!$AD$2:$AD$105,MATCH(LARGE(Bets!$AM$2:$AM$105,5),Bets!$AM$2:$AM$105,0)),"")} -> 1 Ecuador | F17: {=IFERROR(INDEX(Bets!$AE$2:$AE$105,MATCH(LARGE(Bets!$AM$2:$AM$105,5),Bets!$AM$2:$AM$105,0)),"")} -> 5.25 | G17: {=IFERROR(INDEX(Bets!$AF$2:$AF$105,MATCH(LARGE(Bets!$AM$2:$AM$105,5),Bets!$AM$2:$AM$105,0)),"")} -> 0.24733004 | H17: {=IFERROR(INDEX(Bets!$AG$2:$AG$105,MATCH(LARGE(Bets!$AM$2:$AM$105,5),Bets!$AM$2:$AM$105,0)),"")} -> 0.058303159 | I17: {=IFERROR(INDEX(Bets!$AJ$2:$AJ$105,MATCH(LARGE(Bets!$AM$2:$AM$105,5),Bets!$AM$2:$AM$105,0)),"")} -> 15
A18: {=IFERROR(INDEX(Bets!$A$2:$A$105,MATCH(LARGE(Bets!$AM$2:$AM$105,6),Bets!$AM$2:$AM$105,0)),"")} -> 46 | B18: {=IFERROR(INDEX(Bets!$B$2:$B$105,MATCH(LARGE(Bets!$AM$2:$AM$105,6),Bets!$AM$2:$AM$105,0)),"")} -> 46196 | C18: {=IFERROR(INDEX(Bets!$C$2:$C$105,MATCH(LARGE(Bets!$AM$2:$AM$105,6),Bets!$AM$2:$AM$105,0)),"")} -> L | D18: {=IFERROR(INDEX(Bets!$D$2:$D$105,MATCH(LARGE(Bets!$AM$2:$AM$105,6),Bets!$AM$2:$AM$105,0))&" v "&INDEX(Bets!$E$2:$E$105,MATCH(LARGE(Bets!$AM$2:$AM$105,6),Bets!$AM$2:$AM$105,0)),"")} -> England v Ghana | E18: {=IFERROR(INDEX(Bets!$AD$2:$AD$105,MATCH(LARGE(Bets!$AM$2:$AM$105,6),Bets!$AM$2:$AM$105,0)),"")} -> X Draw | F18: {=IFERROR(INDEX(Bets!$AE$2:$AE$105,MATCH(LARGE(Bets!$AM$2:$AM$105,6),Bets!$AM$2:$AM$105,0)),"")} -> 8 | G18: {=IFERROR(INDEX(Bets!$AF$2:$AF$105,MATCH(LARGE(Bets!$AM$2:$AM$105,6),Bets!$AM$2:$AM$105,0)),"")} -> 0.2384812 | H18: {=IFERROR(INDEX(Bets!$AG$2:$AG$105,MATCH(LARGE(Bets!$AM$2:$AM$105,6),Bets!$AM$2:$AM$105,0)),"")} -> 0.032906225 | I18: {=IFERROR(INDEX(Bets!$AJ$2:$AJ$105,MATCH(LARGE(Bets!$AM$2:$AM$105,6),Bets!$AM$2:$AM$105,0)),"")} -> 9
A19: {=IFERROR(INDEX(Bets!$A$2:$A$105,MATCH(LARGE(Bets!$AM$2:$AM$105,7),Bets!$AM$2:$AM$105,0)),"")} -> 29 | B19: {=IFERROR(INDEX(Bets!$B$2:$B$105,MATCH(LARGE(Bets!$AM$2:$AM$105,7),Bets!$AM$2:$AM$105,0)),"")} -> 46192 | C19: {=IFERROR(INDEX(Bets!$C$2:$C$105,MATCH(LARGE(Bets!$AM$2:$AM$105,7),Bets!$AM$2:$AM$105,0)),"")} -> D | D19: {=IFERROR(INDEX(Bets!$D$2:$D$105,MATCH(LARGE(Bets!$AM$2:$AM$105,7),Bets!$AM$2:$AM$105,0))&" v "&INDEX(Bets!$E$2:$E$105,MATCH(LARGE(Bets!$AM$2:$AM$105,7),Bets!$AM$2:$AM$105,0)),"")} -> United States v Australia | E19: {=IFERROR(INDEX(Bets!$AD$2:$AD$105,MATCH(LARGE(Bets!$AM$2:$AM$105,7),Bets!$AM$2:$AM$105,0)),"")} -> 2 Australia | F19: {=IFERROR(INDEX(Bets!$AE$2:$AE$105,MATCH(LARGE(Bets!$AM$2:$AM$105,7),Bets!$AM$2:$AM$105,0)),"")} -> 6.5 | G19: {=IFERROR(INDEX(Bets!$AF$2:$AF$105,MATCH(LARGE(Bets!$AM$2:$AM$105,7),Bets!$AM$2:$AM$105,0)),"")} -> 0.22482113 | H19: {=IFERROR(INDEX(Bets!$AG$2:$AG$105,MATCH(LARGE(Bets!$AM$2:$AM$105,7),Bets!$AM$2:$AM$105,0)),"")} -> 0.035232701 | I19: {=IFERROR(INDEX(Bets!$AJ$2:$AJ$105,MATCH(LARGE(Bets!$AM$2:$AM$105,7),Bets!$AM$2:$AM$105,0)),"")} -> 10
A20: {=IFERROR(INDEX(Bets!$A$2:$A$105,MATCH(LARGE(Bets!$AM$2:$AM$105,8),Bets!$AM$2:$AM$105,0)),"")} -> 59 | B20: {=IFERROR(INDEX(Bets!$B$2:$B$105,MATCH(LARGE(Bets!$AM$2:$AM$105,8),Bets!$AM$2:$AM$105,0)),"")} -> 46198 | C20: {=IFERROR(INDEX(Bets!$C$2:$C$105,MATCH(LARGE(Bets!$AM$2:$AM$105,8),Bets!$AM$2:$AM$105,0)),"")} -> D | D20: {=IFERROR(INDEX(Bets!$D$2:$D$105,MATCH(LARGE(Bets!$AM$2:$AM$105,8),Bets!$AM$2:$AM$105,0))&" v "&INDEX(Bets!$E$2:$E$105,MATCH(LARGE(Bets!$AM$2:$AM$105,8),Bets!$AM$2:$AM$105,0)),"")} -> Turkey v United States | E20: {=IFERROR(INDEX(Bets!$AD$2:$AD$105,MATCH(LARGE(Bets!$AM$2:$AM$105,8),Bets!$AM$2:$AM$105,0)),"")} -> 1 Turkey | F20: {=IFERROR(INDEX(Bets!$AE$2:$AE$105,MATCH(LARGE(Bets!$AM$2:$AM$105,8),Bets!$AM$2:$AM$105,0)),"")} -> 3.7 | G20: {=IFERROR(INDEX(Bets!$AF$2:$AF$105,MATCH(LARGE(Bets!$AM$2:$AM$105,8),Bets!$AM$2:$AM$105,0)),"")} -> 0.2118303 | H20: {=IFERROR(INDEX(Bets!$AG$2:$AG$105,MATCH(LARGE(Bets!$AM$2:$AM$105,8),Bets!$AM$2:$AM$105,0)),"")} -> 0.07450892 | I20: {=IFERROR(INDEX(Bets!$AJ$2:$AJ$105,MATCH(LARGE(Bets!$AM$2:$AM$105,8),Bets!$AM$2:$AM$105,0)),"")} -> 19
A22: MATCHDAY LEDGER — stakes & P&L by day | G22: HOUSE RULES
A23: Date | B23: Games | C23: Staked £ | D23: P&L £ | G23: · Only stake when FINAL ACTION shows 🟢 PLACE.
A24: 46184 | B24: =COUNTIF(Bets!$B$2:$B$105,$A24) -> 2 | C24: =SUMIFS(Bets!$AP$2:$AP$105,Bets!$B$2:$B$105,$A24,Bets!$AN$2:$AN$105,"Y") -> 30 | D24: =SUMIFS(Bets!$AR$2:$AR$105,Bets!$B$2:$B$105,$A24) -> 24.4 | E24: =IF(D24>0,REPT("█",MIN(25,ROUND(D24/4,0))),REPT("░",MIN(25,ROUND(-D24/4,0)))) -> ██████ | G24: · "—" or PASS on most matches = the filter working, not a fault.
A25: 46185 | B25: =COUNTIF(Bets!$B$2:$B$105,$A25) -> 2 | C25: =SUMIFS(Bets!$AP$2:$AP$105,Bets!$B$2:$B$105,$A25,Bets!$AN$2:$AN$105,"Y") -> 44 | D25: =SUMIFS(Bets!$AR$2:$AR$105,Bets!$B$2:$B$105,$A25) -> -3 | E25: =IF(D25>0,REPT("█",MIN(25,ROUND(D25/4,0))),REPT("░",MIN(25,ROUND(-D25/4,0)))) -> ░ | G25: · Fun bets are allowed — small (≤ £5), and STATUS labels them honestly.
A26: 46186 | B26: =COUNTIF(Bets!$B$2:$B$105,$A26) -> 4 | C26: =SUMIFS(Bets!$AP$2:$AP$105,Bets!$B$2:$B$105,$A26,Bets!$AN$2:$AN$105,"Y") -> 60 | D26: =SUMIFS(Bets!$AR$2:$AR$105,Bets!$B$2:$B$105,$A26) -> -7.5 | E26: =IF(D26>0,REPT("█",MIN(25,ROUND(D26/4,0))),REPT("░",MIN(25,ROUND(-D26/4,0)))) -> ░░ | G26: · Never exceed the stake shown. Never chase a loss.
A27: 46187 | B27: =COUNTIF(Bets!$B$2:$B$105,$A27) -> 4 | C27: =SUMIFS(Bets!$AP$2:$AP$105,Bets!$B$2:$B$105,$A27,Bets!$AN$2:$AN$105,"Y") -> 6 | D27: =SUMIFS(Bets!$AR$2:$AR$105,Bets!$B$2:$B$105,$A27) -> -6 | E27: =IF(D27>0,REPT("█",MIN(25,ROUND(D27/4,0))),REPT("░",MIN(25,ROUND(-D27/4,0)))) -> ░░ | G27: · Friends: stake = "£ per £100" × (their bankroll ÷ 100).
A28: 46188 | B28: =COUNTIF(Bets!$B$2:$B$105,$A28) -> 4 | C28: =SUMIFS(Bets!$AP$2:$AP$105,Bets!$B$2:$B$105,$A28,Bets!$AN$2:$AN$105,"Y") -> 0 | D28: =SUMIFS(Bets!$AR$2:$AR$105,Bets!$B$2:$B$105,$A28) -> 0 | E28: =IF(D28>0,REPT("█",MIN(25,ROUND(D28/4,0))),REPT("░",MIN(25,ROUND(-D28/4,0)))) | G28: · 18+ · not financial advice · BeGambleAware.org
A29: 46189 | B29: =COUNTIF(Bets!$B$2:$B$105,$A29) -> 4 | C29: =SUMIFS(Bets!$AP$2:$AP$105,Bets!$B$2:$B$105,$A29,Bets!$AN$2:$AN$105,"Y") -> 0 | D29: =SUMIFS(Bets!$AR$2:$AR$105,Bets!$B$2:$B$105,$A29) -> 0 | E29: =IF(D29>0,REPT("█",MIN(25,ROUND(D29/4,0))),REPT("░",MIN(25,ROUND(-D29/4,0))))
A30: 46190 | B30: =COUNTIF(Bets!$B$2:$B$105,$A30) -> 4 | C30: =SUMIFS(Bets!$AP$2:$AP$105,Bets!$B$2:$B$105,$A30,Bets!$AN$2:$AN$105,"Y") -> 0 | D30: =SUMIFS(Bets!$AR$2:$AR$105,Bets!$B$2:$B$105,$A30) -> 0 | E30: =IF(D30>0,REPT("█",MIN(25,ROUND(D30/4,0))),REPT("░",MIN(25,ROUND(-D30/4,0))))
A31: 46191 | B31: =COUNTIF(Bets!$B$2:$B$105,$A31) -> 4 | C31: =SUMIFS(Bets!$AP$2:$AP$105,Bets!$B$2:$B$105,$A31,Bets!$AN$2:$AN$105,"Y") -> 0 | D31: =SUMIFS(Bets!$AR$2:$AR$105,Bets!$B$2:$B$105,$A31) -> 0 | E31: =IF(D31>0,REPT("█",MIN(25,ROUND(D31/4,0))),REPT("░",MIN(25,ROUND(-D31/4,0))))
A32: 46192 | B32: =COUNTIF(Bets!$B$2:$B$105,$A32) -> 4 | C32: =SUMIFS(Bets!$AP$2:$AP$105,Bets!$B$2:$B$105,$A32,Bets!$AN$2:$AN$105,"Y") -> 0 | D32: =SUMIFS(Bets!$AR$2:$AR$105,Bets!$B$2:$B$105,$A32) -> 0 | E32: =IF(D32>0,REPT("█",MIN(25,ROUND(D32/4,0))),REPT("░",MIN(25,ROUND(-D32/4,0))))
A33: 46193 | B33: =COUNTIF(Bets!$B$2:$B$105,$A33) -> 4 | C33: =SUMIFS(Bets!$AP$2:$AP$105,Bets!$B$2:$B$105,$A33,Bets!$AN$2:$AN$105,"Y") -> 0 | D33: =SUMIFS(Bets!$AR$2:$AR$105,Bets!$B$2:$B$105,$A33) -> 0 | E33: =IF(D33>0,REPT("█",MIN(25,ROUND(D33/4,0))),REPT("░",MIN(25,ROUND(-D33/4,0))))
A34: 46194 | B34: =COUNTIF(Bets!$B$2:$B$105,$A34) -> 4 | C34: =SUMIFS(Bets!$AP$2:$AP$105,Bets!$B$2:$B$105,$A34,Bets!$AN$2:$AN$105,"Y") -> 0 | D34: =SUMIFS(Bets!$AR$2:$AR$105,Bets!$B$2:$B$105,$A34) -> 0 | E34: =IF(D34>0,REPT("█",MIN(25,ROUND(D34/4,0))),REPT("░",MIN(25,ROUND(-D34/4,0))))
A35: 46195 | B35: =COUNTIF(Bets!$B$2:$B$105,$A35) -> 4 | C35: =SUMIFS(Bets!$AP$2:$AP$105,Bets!$B$2:$B$105,$A35,Bets!$AN$2:$AN$105,"Y") -> 0 | D35: =SUMIFS(Bets!$AR$2:$AR$105,Bets!$B$2:$B$105,$A35) -> 0 | E35: =IF(D35>0,REPT("█",MIN(25,ROUND(D35/4,0))),REPT("░",MIN(25,ROUND(-D35/4,0))))
A36: 46196 | B36: =COUNTIF(Bets!$B$2:$B$105,$A36) -> 4 | C36: =SUMIFS(Bets!$AP$2:$AP$105,Bets!$B$2:$B$105,$A36,Bets!$AN$2:$AN$105,"Y") -> 0 | D36: =SUMIFS(Bets!$AR$2:$AR$105,Bets!$B$2:$B$105,$A36) -> 0 | E36: =IF(D36>0,REPT("█",MIN(25,ROUND(D36/4,0))),REPT("░",MIN(25,ROUND(-D36/4,0))))
A37: 46197 | B37: =COUNTIF(Bets!$B$2:$B$105,$A37) -> 6 | C37: =SUMIFS(Bets!$AP$2:$AP$105,Bets!$B$2:$B$105,$A37,Bets!$AN$2:$AN$105,"Y") -> 7.5 | D37: =SUMIFS(Bets!$AR$2:$AR$105,Bets!$B$2:$B$105,$A37) -> -7.5 | E37: =IF(D37>0,REPT("█",MIN(25,ROUND(D37/4,0))),REPT("░",MIN(25,ROUND(-D37/4,0)))) -> ░░
A38: 46198 | B38: =COUNTIF(Bets!$B$2:$B$105,$A38) -> 6 | C38: =SUMIFS(Bets!$AP$2:$AP$105,Bets!$B$2:$B$105,$A38,Bets!$AN$2:$AN$105,"Y") -> 0 | D38: =SUMIFS(Bets!$AR$2:$AR$105,Bets!$B$2:$B$105,$A38) -> 0 | E38: =IF(D38>0,REPT("█",MIN(25,ROUND(D38/4,0))),REPT("░",MIN(25,ROUND(-D38/4,0))))
A39: 46199 | B39: =COUNTIF(Bets!$B$2:$B$105,$A39) -> 6 | C39: =SUMIFS(Bets!$AP$2:$AP$105,Bets!$B$2:$B$105,$A39,Bets!$AN$2:$AN$105,"Y") -> 0 | D39: =SUMIFS(Bets!$AR$2:$AR$105,Bets!$B$2:$B$105,$A39) -> 0 | E39: =IF(D39>0,REPT("█",MIN(25,ROUND(D39/4,0))),REPT("░",MIN(25,ROUND(-D39/4,0))))
A40: 46200 | B40: =COUNTIF(Bets!$B$2:$B$105,$A40) -> 6 | C40: =SUMIFS(Bets!$AP$2:$AP$105,Bets!$B$2:$B$105,$A40,Bets!$AN$2:$AN$105,"Y") -> 31 | D40: =SUMIFS(Bets!$AR$2:$AR$105,Bets!$B$2:$B$105,$A40) -> -31 | E40: =IF(D40>0,REPT("█",MIN(25,ROUND(D40/4,0))),REPT("░",MIN(25,ROUND(-D40/4,0)))) -> ░░░░░░░░

Sheet Live
A1: LIVE STATE — auto-polled from /live_state.json
A3: Source URL | B3: https://wc26-matchday-intelligence.vercel.app/live_state.json
A4: Predictions URL | B4: https://wc26-matchday-intelligence.vercel.app/predictions_live.json
A5: Intel URL | B5: https://wc26-matchday-intelligence.vercel.app/matchday_intelligence.json
A6: Field | B6: Value | C6: Mirrors to Method
A7: Last poll (UTC) | B7: 46212.365 | C7: B58
A8: Mode | B8: live | C8: B59
A9: Completed matches | B9: 96 | C9: B60
A10: Provider mode | B10: active | C10: B61
A11: Warnings (joined) | C11: B62
A12: Source | B12: api_football
A13: Last model refresh (UTC) | C13: B57
A14: Simulation rerun this tick | B14: FALSE
A15: live_state last_updated_utc | B15: 2026-07-09T15:40:48.645956+00:00
A17: STATUS | B17: =IF(B7="","⚠ Apps Script not run yet — open Extensions ▸ Apps Script ▸ run installEngine()","✓ live polling active · last poll "&TEXT(B7,"yyyy-mm-dd hh:mm")) -> ✓ live polling active · last poll 2026-07-09 08:45
A18: — MATCHDAY INTELLIGENCE (auto) —
A19: Intel generated at (UTC) | B19: 2026-07-09T14:37:39.132850+00:00 | C19: mirrors to Method!B67
A20: Intel total components | B20: 236 | C20: B68
A21: Intel teams affected | B21: 48 | C21: B69
A22: Intel matches affected | B22: 23 | C22: B70
A23: Intel aggregate caps hit | B23: 2 | C23: B71
A24: Intel warnings
A25: Matches in play right now | B25: 0 | C25: see In-Play sheet
A26: Stale-feed warning | C26: >15 min trips PAUSE
B27: ⚠ calibration OOB (clamp to last bin): home=1/72 draw=6/72 away=2/72 · 32 knockout row(s) skipped
A28: Endpoints — clear B3/B4/B5 to revert to v2.3 defaults.
A30: This sheet is read-only output from the Apps Script poller. If the values stay blank, open Extensions ▸ Apps Script and run installEngine() once. The script then refreshes model probabilities into Bets!I:K (skipping any row already flagged as Placed=Y) and writes a snapshot of /live_state.json here every 5 minutes.

Sheet Bets
A1: # | B1: Date | C1: Grp | D1: Home | E1: Away | F1: Venue | G1: KO local | H1: KO UK | I1: Model pH | J1: Model pD | K1: Model pA | L1: Odds H | M1: Odds D | N1: Odds A | O1: imp H | P1: imp D | Q1: imp A | R1: Overround | S1: mkt H | T1: mkt D | U1: mkt A | V1: blend H | W1: blend D | X1: blend A | Y1: EV H | Z1: EV D | AA1: EV A | AB1: pick# | AC1: code | AD1: PICK | AE1: Odds | AF1: EV % | AG1: Edge pp | AH1: DECISION | AI1: £ / £100 bank | AJ1: ENGINE STAKE £ | AK1: p(blend) | AL1: Kelly f | AM1: rankkey | AN1: Placed? | AO1: Odds taken | AP1: Stake £ | AQ1: Result | AR1: P&L £ | AS1: Cum P&L | AT1: WHY (plain English) | AU1: STATUS | AV1: Backed | AW1: dec@bet | AX1: eng£@bet | AY1: pick@bet | AZ1: class | BA1: eng£ eff | BB1: intel Δ | BC1: pH (cal) | BD1: pD (cal) | BE1: pA (cal) | BF1: intel breakdown | BG1: altitude m | BH1: climate | BI1: home travel km
A2: 1 | B2: 46184 | C2: A | D2: Mexico | E2: South Africa | F2: Mexico City | G2: 0.54166667 | H2: 0.83333333 | I2: 0.7008 | J2: 0.2117 | K2: 0.0876 | L2: =IF(Matchday!E4="","",Matchday!E4) -> 1.42 | M2: =IF(Matchday!F4="","",Matchday!F4) -> 4.5 | N2: =IF(Matchday!G4="","",Matchday!G4) -> 8.5 | O2: =IF(L2="","",1/L2) -> 0.70422535 | P2: =IF(M2="","",1/M2) -> 0.22222222 | Q2: =IF(N2="","",1/N2) -> 0.11764706 | R2: =IF(COUNT(L2:N2)<3,"",O2+P2+Q2) -> 1.0440946 | S2: {=IF($R2="","",IF(Method!$B$56="proportional",O2/$R2,IF(Method!$B$56="power",IFERROR(INDEX(power_devig($L2,$M2,$N2),1,1),O2/$R2),IFERROR(INDEX(shin($L2,$M2,$N2),1,1),O2/$R2))))} -> 0.68567733 | T2: {=IF($R2="","",IF(Method!$B$56="proportional",P2/$R2,IF(Method!$B$56="power",IFERROR(INDEX(power_devig($L2,$M2,$N2),2,1),P2/$R2),IFERROR(INDEX(shin($L2,$M2,$N2),2,1),P2/$R2))))} -> 0.20878432 | U2: {=IF($R2="","",IF(Method!$B$56="proportional",Q2/$R2,IF(Method!$B$56="power",IFERROR(INDEX(power_devig($L2,$M2,$N2),3,1),Q2/$R2),IFERROR(INDEX(shin($L2,$M2,$N2),3,1),Q2/$R2))))} -> 0.10553835 | V2: =IF(S2="","",Method!$B$4*IF(BC2="",I2,BC2)+(1-Method!$B$4)*S2/($S2+$T2+$U2)) -> 0.68044333 | W2: =IF(T2="","",Method!$B$4*IF(BD2="",J2,BD2)+(1-Method!$B$4)*T2/($S2+$T2+$U2)) -> 0.21958232 | X2: =IF(U2="","",Method!$B$4*IF(BE2="",K2,BE2)+(1-Method!$B$4)*U2/($S2+$T2+$U2)) -> 0.099974353 | Y2: =IF(V2="","",V2*L2-1) -> -0.033770477 | Z2: =IF(W2="","",W2*M2-1) -> -0.011879559 | AA2: =IF(X2="","",X2*N2-1) -> -0.150218 | AB2: =IF(Y2="","",MATCH(MAX(Y2:AA2),Y2:AA2,0)) -> 2 | AC2: =IF(AB2="","",CHOOSE(AB2,"H","D","A")) -> D | AD2: =IF(AB2="","",CHOOSE(AB2,"1 "&D2,"X Draw","2 "&E2)) -> X Draw | AE2: =IF(AB2="","",INDEX(L2:N2,1,AB2)) -> 4.5 | AF2: =IF(AB2="","",INDEX(Y2:AA2,1,AB2)) -> -0.011879559 | AG2: =IF(AB2="","",INDEX(V2:X2,1,AB2)-INDEX(S2:U2,1,AB2)) -> 0.010798002 | AH2: {=IF(AB2="","· enter odds",IF(OR(AF2>Method!$B$87,IFERROR(INDEX(BC2:BE2,1,AB2)/INDEX(S2:U2,1,AB2),0)>Method!$B$88),"PASS",IF(AND(AF2>=Method!$B$7,AG2>=Method!$B$8),"BET","PASS")))} -> PASS | AI2: =IF(AH2<>"BET",0,ROUND(MIN(Method!$B$6,Method!$B$5*AL2)*100,1)) -> 0 | AJ2: =IF(OR(AH2<>"BET",Method!$B$55=TRUE()),0,IF(AI2*Method!$B$10/100<Method!$B$9,0,ROUND(AI2*Method!$B$10/100,0))) -> 0 | AK2: =IF(AB2="","",INDEX(V2:X2,1,AB2)) -> 0.21958232 | AL2: =IF(AH2<>"BET","",MAX(0,(AK2*AE2-1)/(AE2-1))) | AM2: =IF(AH2="BET",AF2+A2/1000000,"") | AN2: =IF(Matchday!N4="","",Matchday!N4) -> Y | AO2: =IF(Matchday!P4="","",Matchday!P4) -> 1.42 | AP2: =IF(Matchday!Q4="","",Matchday!Q4) -> 20 | AQ2: =IF(Matchday!R4="","",Matchday!R4) -> H | AR2: =IF(OR(AN2<>"Y",AQ2="",AV2=""),"",IF(AQ2="Void",0,IF(AQ2=AV2,ROUND(AP2*(AO2-1),2),-AP2))) -> 8.4 | AS2: =IF(AR2="","",SUM($AR$2:AR2)) -> 8.4 | AT2: =IFERROR(__xludf.DUMMYFUNCTION("IF(AB2="""",""Type the 3 odds on the Matchday tab"",IF(Method!$B$55=TRUE(),IF(Method!$B$81=TRUE(),IF(REGEXMATCH(LOWER(Method!$B$63),""circuit""),""🛑 PAUSED — circuit breaker upstream; wait for a clean live refresh."",IF(REGEXMATCH(LOWER(Method!$B$63),""p"&"ipeline""),""🛑 PAUSED — live pipeline warning; check Live!B11/Method!B62 before betting."",IF(REGEXMATCH(LOWER(Method!$B$63),""missing""),""🛑 PAUSED — feed timestamp missing; refresh feed before betting."",""🛑 PAUSED — feed stale > 25 min — check Live "&"tab; refresh feed before betting.""))),IF(Method!$B$51>=Method!$B$52,""🛑 PAUSED — drawdown ""&TEXT(Method!$B$51,""0.0%"")&"" ≥ ""&TEXT(Method!$B$52,""0.0%"")&"". Set Method!B54=Y to override."",""🛑 PAUSED — see Method!B62/B63/B81 for cause; do not overr"&"ide stale/circuit-breaker/pipeline pauses."")),IF(AH2=""BET"",IF(AJ2=0,""Edge found but stake rounds under £""&Method!$B$9&"" — skip"",IF(AND(AE2>=6,AG2>=0.15),""🟡 WAIT — long-shot review: odds ""&TEXT(AE2,""0.00"")&"" + edge ""&TEXT(AG2,""0.0%"")&"" — v"&"erify sharp-book + team news + stake comfort before Placed=Y"",""Value found: EV ""&TEXT(AF2,""0.0%"")&"", edge ""&TEXT(AG2,""0.0%""))),IF(OR(AF2>Method!$B$87,IFERROR(INDEX(BC2:BE2,1,AB2)/INDEX(S2:U2,1,AB2),0)>Method!$B$88),""🛑 Tail trap — auto-PASS · EV"&" ""&TEXT(AF2,""0.0%"")&"" (cap ""&TEXT(Method!$B$87,""0%"")&"") · model/market ""&TEXT(IFERROR(INDEX(BC2:BE2,1,AB2)/INDEX(S2:U2,1,AB2),0),""0.0"")&""× (cap ""&TEXT(Method!$B$88,""0.0"")&""×)"",IF(AF2<Method!$B$7,""Price too short — EV ""&TEXT(AF2,""0.0%"""&")&"" (need ""&TEXT(Method!$B$7,""0.0%"")&""+)"",""Model ≈ market — edge ""&TEXT(AG2,""0.0%"")&"" (need ""&TEXT(Method!$B$8,""0.0%"")&""+)"")))))"),"Price too short — EV -1.2% (need 2.5%+)") -> Price too short — EV -1.2% (need 2.5%+) | AU2: =IF(AN2<>"Y","",IF(AH2="· enter odds","⚠ type the 3 odds (1/X/2) to grade this bet",IF(OR(AV2="",AO2="",AP2=""),"⚠ log backed pick, odds & stake",IF(AZ2<>"BET","⚠ FUN BET — engine said pass · staked £"&AP2&" vs engine £"&BA2,IF(AV2<>IF(AY2="",AC2,AY2),"⚠ backed "&AV2&" but engine pick was "&IF(AY2="",AC2,AY2),IF(AP2>BA2,"⚠ stake over engine £"&BA2,IF(ABS(AO2-IFERROR(INDEX(L2:N2,1,MATCH(AV2,{"H","D","A"},0)),AE2))>0.02,"⚠ odds moved — re-check value","✓ engine bet"))))))) -> ⚠ FUN BET — engine said pass · staked £20 vs engine £0 | AV2: =IF(Matchday!O4="","",Matchday!O4) -> H | AW2: PASS | AX2: 0 | AY2: H | AZ2: =IF(AW2="",AH2,AW2) -> PASS | BA2: =IF(AX2<>"",AX2,IF(AH2<>"BET",0,IF(AI2*Method!$B$10/100<Method!$B$9,0,ROUND(AI2*Method!$B$10/100,0)))) -> 0 | BB2: -22.38 | BC2: 0.67072304 | BD2: 0.23963575 | BE2: 0.089641212 | BF2: Mexico team-wide: +7 · South Africa team-wide: -29 | BG2: 2240 | BH2: high_altitude_mild | BI2: 0
A3: 2 | B3: 46184 | C3: A | D3: South Korea | E3: Czechia | F3: Zapopan | G3: 0.83333333 | H3: 03:00 +1d | I3: 0.44370918 | J3: 0.29067093 | K3: 0.26561988 | L3: =IF(Matchday!E5="","",Matchday!E5) -> 2.7 | M3: =IF(Matchday!F5="","",Matchday!F5) -> 3.1 | N3: =IF(Matchday!G5="","",Matchday!G5) -> 2.8 | O3: =IF(L3="","",1/L3) -> 0.37037037 | P3: =IF(M3="","",1/M3) -> 0.32258065 | Q3: =IF(N3="","",1/N3) -> 0.35714286 | R3: =IF(COUNT(L3:N3)<3,"",O3+P3+Q3) -> 1.0500939 | S3: {=IF($R3="","",IF(Method!$B$56="proportional",O3/$R3,IF(Method!$B$56="power",IFERROR(INDEX(power_devig($L3,$M3,$N3),1,1),O3/$R3),IFERROR(INDEX(shin($L3,$M3,$N3),1,1),O3/$R3))))} -> 0.35342082 | T3: {=IF($R3="","",IF(Method!$B$56="proportional",P3/$R3,IF(Method!$B$56="power",IFERROR(INDEX(power_devig($L3,$M3,$N3),2,1),P3/$R3),IFERROR(INDEX(shin($L3,$M3,$N3),2,1),P3/$R3))))} -> 0.30622296 | U3: {=IF($R3="","",IF(Method!$B$56="proportional",Q3/$R3,IF(Method!$B$56="power",IFERROR(INDEX(power_devig($L3,$M3,$N3),3,1),Q3/$R3),IFERROR(INDEX(shin($L3,$M3,$N3),3,1),Q3/$R3))))} -> 0.34035623 | V3: =IF(S3="","",Method!$B$4*IF(BC3="",I3,BC3)+(1-Method!$B$4)*S3/($S3+$T3+$U3)) -> 0.38650219 | W3: =IF(T3="","",Method!$B$4*IF(BD3="",J3,BD3)+(1-Method!$B$4)*T3/($S3+$T3+$U3)) -> 0.29234075 | X3: =IF(U3="","",Method!$B$4*IF(BE3="",K3,BE3)+(1-Method!$B$4)*U3/($S3+$T3+$U3)) -> 0.32115706 | Y3: =IF(V3="","",V3*L3-1) -> 0.043555918 | Z3: =IF(W3="","",W3*M3-1) -> -0.09374369 | AA3: =IF(X3="","",X3*N3-1) -> -0.10076022 | AB3: =IF(Y3="","",MATCH(MAX(Y3:AA3),Y3:AA3,0)) -> 1 | AC3: =IF(AB3="","",CHOOSE(AB3,"H","D","A")) -> H | AD3: =IF(AB3="","",CHOOSE(AB3,"1 "&D3,"X Draw","2 "&E3)) -> 1 South Korea | AE3: =IF(AB3="","",INDEX(L3:N3,1,AB3)) -> 2.7 | AF3: =IF(AB3="","",INDEX(Y3:AA3,1,AB3)) -> 0.043555918 | AG3: =IF(AB3="","",INDEX(V3:X3,1,AB3)-INDEX(S3:U3,1,AB3)) -> 0.033081377 | AH3: {=IF(AB3="","· enter odds",IF(OR(AF3>Method!$B$87,IFERROR(INDEX(BC3:BE3,1,AB3)/INDEX(S3:U3,1,AB3),0)>Method!$B$88),"PASS",IF(AND(AF3>=Method!$B$7,AG3>=Method!$B$8),"BET","PASS")))} -> BET | AI3: =IF(AH3<>"BET",0,ROUND(MIN(Method!$B$6,Method!$B$5*AL3)*100,1)) -> 0.6 | AJ3: =IF(OR(AH3<>"BET",Method!$B$55=TRUE()),0,IF(AI3*Method!$B$10/100<Method!$B$9,0,ROUND(AI3*Method!$B$10/100,0))) -> 6 | AK3: =IF(AB3="","",INDEX(V3:X3,1,AB3)) -> 0.38650219 | AL3: =IF(AH3<>"BET","",MAX(0,(AK3*AE3-1)/(AE3-1))) -> 0.025621128 | AM3: =IF(AH3="BET",AF3+A3/1000000,"") -> 0.043557918 | AN3: =IF(Matchday!N5="","",Matchday!N5) -> Y | AO3: =IF(Matchday!P5="","",Matchday!P5) -> 2.6 | AP3: =IF(Matchday!Q5="","",Matchday!Q5) -> 10 | AQ3: =IF(Matchday!R5="","",Matchday!R5) -> H | AR3: =IF(OR(AN3<>"Y",AQ3="",AV3=""),"",IF(AQ3="Void",0,IF(AQ3=AV3,ROUND(AP3*(AO3-1),2),-AP3))) -> 16 | AS3: =IF(AR3="","",SUM($AR$2:AR3)) -> 24.4 | AT3: =IFERROR(__xludf.DUMMYFUNCTION("IF(AB3="""",""Type the 3 odds on the Matchday tab"",IF(Method!$B$55=TRUE(),IF(Method!$B$81=TRUE(),IF(REGEXMATCH(LOWER(Method!$B$63),""circuit""),""🛑 PAUSED — circuit breaker upstream; wait for a clean live refresh."",IF(REGEXMATCH(LOWER(Method!$B$63),""p"&"ipeline""),""🛑 PAUSED — live pipeline warning; check Live!B11/Method!B62 before betting."",IF(REGEXMATCH(LOWER(Method!$B$63),""missing""),""🛑 PAUSED — feed timestamp missing; refresh feed before betting."",""🛑 PAUSED — feed stale > 25 min — check Live "&"tab; refresh feed before betting.""))),IF(Method!$B$51>=Method!$B$52,""🛑 PAUSED — drawdown ""&TEXT(Method!$B$51,""0.0%"")&"" ≥ ""&TEXT(Method!$B$52,""0.0%"")&"". Set Method!B54=Y to override."",""🛑 PAUSED — see Method!B62/B63/B81 for cause; do not overr"&"ide stale/circuit-breaker/pipeline pauses."")),IF(AH3=""BET"",IF(AJ3=0,""Edge found but stake rounds under £""&Method!$B$9&"" — skip"",IF(AND(AE3>=6,AG3>=0.15),""🟡 WAIT — long-shot review: odds ""&TEXT(AE3,""0.00"")&"" + edge ""&TEXT(AG3,""0.0%"")&"" — v"&"erify sharp-book + team news + stake comfort before Placed=Y"",""Value found: EV ""&TEXT(AF3,""0.0%"")&"", edge ""&TEXT(AG3,""0.0%""))),IF(OR(AF3>Method!$B$87,IFERROR(INDEX(BC3:BE3,1,AB3)/INDEX(S3:U3,1,AB3),0)>Method!$B$88),""🛑 Tail trap — auto-PASS · EV"&" ""&TEXT(AF3,""0.0%"")&"" (cap ""&TEXT(Method!$B$87,""0%"")&"") · model/market ""&TEXT(IFERROR(INDEX(BC3:BE3,1,AB3)/INDEX(S3:U3,1,AB3),0),""0.0"")&""× (cap ""&TEXT(Method!$B$88,""0.0"")&""×)"",IF(AF3<Method!$B$7,""Price too short — EV ""&TEXT(AF3,""0.0%"""&")&"" (need ""&TEXT(Method!$B$7,""0.0%"")&""+)"",""Model ≈ market — edge ""&TEXT(AG3,""0.0%"")&"" (need ""&TEXT(Method!$B$8,""0.0%"")&""+)"")))))"),"Value found: EV 4.4%, edge 3.3%") -> Value found: EV 4.4%, edge 3.3% | AU3: =IF(AN3<>"Y","",IF(AH3="· enter odds","⚠ type the 3 odds (1/X/2) to grade this bet",IF(OR(AV3="",AO3="",AP3=""),"⚠ log backed pick, odds & stake",IF(AZ3<>"BET","⚠ FUN BET — engine said pass · staked £"&AP3&" vs engine £"&BA3,IF(AV3<>IF(AY3="",AC3,AY3),"⚠ backed "&AV3&" but engine pick was "&IF(AY3="",AC3,AY3),IF(AP3>BA3,"⚠ stake over engine £"&BA3,IF(ABS(AO3-IFERROR(INDEX(L3:N3,1,MATCH(AV3,{"H","D","A"},0)),AE3))>0.02,"⚠ odds moved — re-check value","✓ engine bet"))))))) -> ⚠ stake over engine £3 | AV3: =IF(Matchday!O5="","",Matchday!O5) -> H | AW3: BET | AX3: 3 | AY3: H | AZ3: =IF(AW3="",AH3,AW3) -> BET | BA3: =IF(AX3<>"",AX3,IF(AH3<>"BET",0,IF(AI3*Method!$B$10/100<Method!$B$9,0,ROUND(AI3*Method!$B$10/100,0)))) -> 3 | BB3: -20.33 | BC3: 0.44793903 | BD3: 0.2665595 | BE3: 0.28550147 | BF3: Czechia team-wide: -16 · Czechia weather: -4 · South Korea team-wide: +1 · South Korea weather: -1 | BG3: 1560 | BH3: warm_humid | BI3: 0
A4: 3 | B4: 46185 | C4: B | D4: Canada | E4: Bosnia and Herzegovina | F4: Toronto | G4: 0.625 | H4: 0.83333333 | I4: 0.69750662 | J4: 0.2132834 | K4: 0.089209979 | L4: =IF(Matchday!E6="","",Matchday!E6) -> 1.85 | M4: =IF(Matchday!F6="","",Matchday!F6) -> 3.5 | N4: =IF(Matchday!G6="","",Matchday!G6) -> 4.5 | O4: =IF(L4="","",1/L4) -> 0.54054054 | P4: =IF(M4="","",1/M4) -> 0.28571429 | Q4: =IF(N4="","",1/N4) -> 0.22222222 | R4: =IF(COUNT(L4:N4)<3,"",O4+P4+Q4) -> 1.048477 | S4: {=IF($R4="","",IF(Method!$B$56="proportional",O4/$R4,IF(Method!$B$56="power",IFERROR(INDEX(power_devig($L4,$M4,$N4),1,1),O4/$R4),IFERROR(INDEX(shin($L4,$M4,$N4),1,1),O4/$R4))))} -> 0.52211289 | T4: {=IF($R4="","",IF(Method!$B$56="proportional",P4/$R4,IF(Method!$B$56="power",IFERROR(INDEX(power_devig($L4,$M4,$N4),2,1),P4/$R4),IFERROR(INDEX(shin($L4,$M4,$N4),2,1),P4/$R4))))} -> 0.27029207 | U4: {=IF($R4="","",IF(Method!$B$56="proportional",Q4/$R4,IF(Method!$B$56="power",IFERROR(INDEX(power_devig($L4,$M4,$N4),3,1),Q4/$R4),IFERROR(INDEX(shin($L4,$M4,$N4),3,1),Q4/$R4))))} -> 0.20759504 | V4: =IF(S4="","",Method!$B$4*IF(BC4="",I4,BC4)+(1-Method!$B$4)*S4/($S4+$T4+$U4)) -> 0.57294231 | W4: =IF(T4="","",Method!$B$4*IF(BD4="",J4,BD4)+(1-Method!$B$4)*T4/($S4+$T4+$U4)) -> 0.26015932 | X4: =IF(U4="","",Method!$B$4*IF(BE4="",K4,BE4)+(1-Method!$B$4)*U4/($S4+$T4+$U4)) -> 0.16689837 | Y4: =IF(V4="","",V4*L4-1) -> 0.059943274 | Z4: =IF(W4="","",W4*M4-1) -> -0.089442368 | AA4: =IF(X4="","",X4*N4-1) -> -0.24895735 | AB4: =IF(Y4="","",MATCH(MAX(Y4:AA4),Y4:AA4,0)) -> 1 | AC4: =IF(AB4="","",CHOOSE(AB4,"H","D","A")) -> H | AD4: =IF(AB4="","",CHOOSE(AB4,"1 "&D4,"X Draw","2 "&E4)) -> 1 Canada | AE4: =IF(AB4="","",INDEX(L4:N4,1,AB4)) -> 1.85 | AF4: =IF(AB4="","",INDEX(Y4:AA4,1,AB4)) -> 0.059943274 | AG4: =IF(AB4="","",INDEX(V4:X4,1,AB4)-INDEX(S4:U4,1,AB4)) -> 0.050829423 | AH4: {=IF(AB4="","· enter odds",IF(OR(AF4>Method!$B$87,IFERROR(INDEX(BC4:BE4,1,AB4)/INDEX(S4:U4,1,AB4),0)>Method!$B$88),"PASS",IF(AND(AF4>=Method!$B$7,AG4>=Method!$B$8),"BET","PASS")))} -> BET | AI4: =IF(AH4<>"BET",0,ROUND(MIN(Method!$B$6,Method!$B$5*AL4)*100,1)) -> 1.8 | AJ4: =IF(OR(AH4<>"BET",Method!$B$55=TRUE()),0,IF(AI4*Method!$B$10/100<Method!$B$9,0,ROUND(AI4*Method!$B$10/100,0))) -> 17 | AK4: =IF(AB4="","",INDEX(V4:X4,1,AB4)) -> 0.57294231 | AL4: =IF(AH4<>"BET","",MAX(0,(AK4*AE4-1)/(AE4-1))) -> 0.070521499 | AM4: =IF(AH4="BET",AF4+A4/1000000,"") -> 0.059946274 | AN4: =IF(Matchday!N6="","",Matchday!N6) -> Y | AO4: =IF(Matchday!P6="","",Matchday!P6) -> 1.85 | AP4: =IF(Matchday!Q6="","",Matchday!Q6) -> 24 | AQ4: =IF(Matchday!R6="","",Matchday!R6) -> D | AR4: =IF(OR(AN4<>"Y",AQ4="",AV4=""),"",IF(AQ4="Void",0,IF(AQ4=AV4,ROUND(AP4*(AO4-1),2),-AP4))) -> -24 | AS4: =IF(AR4="","",SUM($AR$2:AR4)) -> 0.4 | AT4: =IFERROR(__xludf.DUMMYFUNCTION("IF(AB4="""",""Type the 3 odds on the Matchday tab"",IF(Method!$B$55=TRUE(),IF(Method!$B$81=TRUE(),IF(REGEXMATCH(LOWER(Method!$B$63),""circuit""),""🛑 PAUSED — circuit breaker upstream; wait for a clean live refresh."",IF(REGEXMATCH(LOWER(Method!$B$63),""p"&"ipeline""),""🛑 PAUSED — live pipeline warning; check Live!B11/Method!B62 before betting."",IF(REGEXMATCH(LOWER(Method!$B$63),""missing""),""🛑 PAUSED — feed timestamp missing; refresh feed before betting."",""🛑 PAUSED — feed stale > 25 min — check Live "&"tab; refresh feed before betting.""))),IF(Method!$B$51>=Method!$B$52,""🛑 PAUSED — drawdown ""&TEXT(Method!$B$51,""0.0%"")&"" ≥ ""&TEXT(Method!$B$52,""0.0%"")&"". Set Method!B54=Y to override."",""🛑 PAUSED — see Method!B62/B63/B81 for cause; do not overr"&"ide stale/circuit-breaker/pipeline pauses."")),IF(AH4=""BET"",IF(AJ4=0,""Edge found but stake rounds under £""&Method!$B$9&"" — skip"",IF(AND(AE4>=6,AG4>=0.15),""🟡 WAIT — long-shot review: odds ""&TEXT(AE4,""0.00"")&"" + edge ""&TEXT(AG4,""0.0%"")&"" — v"&"erify sharp-book + team news + stake comfort before Placed=Y"",""Value found: EV ""&TEXT(AF4,""0.0%"")&"", edge ""&TEXT(AG4,""0.0%""))),IF(OR(AF4>Method!$B$87,IFERROR(INDEX(BC4:BE4,1,AB4)/INDEX(S4:U4,1,AB4),0)>Method!$B$88),""🛑 Tail trap — auto-PASS · EV"&" ""&TEXT(AF4,""0.0%"")&"" (cap ""&TEXT(Method!$B$87,""0%"")&"") · model/market ""&TEXT(IFERROR(INDEX(BC4:BE4,1,AB4)/INDEX(S4:U4,1,AB4),0),""0.0"")&""× (cap ""&TEXT(Method!$B$88,""0.0"")&""×)"",IF(AF4<Method!$B$7,""Price too short — EV ""&TEXT(AF4,""0.0%"""&")&"" (need ""&TEXT(Method!$B$7,""0.0%"")&""+)"",""Model ≈ market — edge ""&TEXT(AG4,""0.0%"")&"" (need ""&TEXT(Method!$B$8,""0.0%"")&""+)"")))))"),"Value found: EV 6.0%, edge 5.1%") -> Value found: EV 6.0%, edge 5.1% | AU4: =IF(AN4<>"Y","",IF(AH4="· enter odds","⚠ type the 3 odds (1/X/2) to grade this bet",IF(OR(AV4="",AO4="",AP4=""),"⚠ log backed pick, odds & stake",IF(AZ4<>"BET","⚠ FUN BET — engine said pass · staked £"&AP4&" vs engine £"&BA4,IF(AV4<>IF(AY4="",AC4,AY4),"⚠ backed "&AV4&" but engine pick was "&IF(AY4="",AC4,AY4),IF(AP4>BA4,"⚠ stake over engine £"&BA4,IF(ABS(AO4-IFERROR(INDEX(L4:N4,1,MATCH(AV4,{"H","D","A"},0)),AE4))>0.02,"⚠ odds moved — re-check value","✓ engine bet"))))))) -> ⚠ stake over engine £12 | AV4: =IF(Matchday!O6="","",Matchday!O6) -> H | AW4: BET | AX4: 12 | AY4: H | AZ4: =IF(AW4="",AH4,AW4) -> BET | BA4: =IF(AX4<>"",AX4,IF(AH4<>"BET",0,IF(AI4*Method!$B$10/100<Method!$B$9,0,ROUND(AI4*Method!$B$10/100,0)))) -> 12 | BB4: -27.24 | BC4: 0.66733981 | BD4: 0.24134137 | BE4: 0.091318821 | BF4: Bosnia and Herzegovina team-wide: -18 · Canada team-wide: -9 | BG4: 76 | BH4: mild | BI4: 0
A5: 4 | B5: 46185 | C5: D | D5: United States | E5: Paraguay | F5: Inglewood | G5: 0.75 | H5: 02:00 +1d | I5: 0.48548732 | J5: 0.2800987 | K5: 0.23441398 | L5: =IF(Matchday!E7="","",Matchday!E7) -> 2.18 | M5: =IF(Matchday!F7="","",Matchday!F7) -> 3.3 | N5: =IF(Matchday!G7="","",Matchday!G7) -> 4.1 | O5: =IF(L5="","",1/L5) -> 0.4587156 | P5: =IF(M5="","",1/M5) -> 0.3030303 | Q5: =IF(N5="","",1/N5) -> 0.24390244 | R5: =IF(COUNT(L5:N5)<3,"",O5+P5+Q5) -> 1.0056483 | S5: {=IF($R5="","",IF(Method!$B$56="proportional",O5/$R5,IF(Method!$B$56="power",IFERROR(INDEX(power_devig($L5,$M5,$N5),1,1),O5/$R5),IFERROR(INDEX(shin($L5,$M5,$N5),1,1),O5/$R5))))} -> 0.4566588 | T5: {=IF($R5="","",IF(Method!$B$56="proportional",P5/$R5,IF(Method!$B$56="power",IFERROR(INDEX(power_devig($L5,$M5,$N5),2,1),P5/$R5),IFERROR(INDEX(shin($L5,$M5,$N5),2,1),P5/$R5))))} -> 0.30119272 | U5: {=IF($R5="","",IF(Method!$B$56="proportional",Q5/$R5,IF(Method!$B$56="power",IFERROR(INDEX(power_devig($L5,$M5,$N5),3,1),Q5/$R5),IFERROR(INDEX(shin($L5,$M5,$N5),3,1),Q5/$R5))))} -> 0.24214849 | V5: =IF(S5="","",Method!$B$4*IF(BC5="",I5,BC5)+(1-Method!$B$4)*S5/($S5+$T5+$U5)) -> 0.46585091 | W5: =IF(T5="","",Method!$B$4*IF(BD5="",J5,BD5)+(1-Method!$B$4)*T5/($S5+$T5+$U5)) -> 0.29055699 | X5: =IF(U5="","",Method!$B$4*IF(BE5="",K5,BE5)+(1-Method!$B$4)*U5/($S5+$T5+$U5)) -> 0.24359209 | Y5: =IF(V5="","",V5*L5-1) -> 0.015554992 | Z5: =IF(W5="","",W5*M5-1) -> -0.041161927 | AA5: =IF(X5="","",X5*N5-1) -> -0.0012724128 | AB5: =IF(Y5="","",MATCH(MAX(Y5:AA5),Y5:AA5,0)) -> 1 | AC5: =IF(AB5="","",CHOOSE(AB5,"H","D","A")) -> H | AD5: =IF(AB5="","",CHOOSE(AB5,"1 "&D5,"X Draw","2 "&E5)) -> 1 United States | AE5: =IF(AB5="","",INDEX(L5:N5,1,AB5)) -> 2.18 | AF5: =IF(AB5="","",INDEX(Y5:AA5,1,AB5)) -> 0.015554992 | AG5: =IF(AB5="","",INDEX(V5:X5,1,AB5)-INDEX(S5:U5,1,AB5)) -> 0.0091921177 | AH5: {=IF(AB5="","· enter odds",IF(OR(AF5>Method!$B$87,IFERROR(INDEX(BC5:BE5,1,AB5)/INDEX(S5:U5,1,AB5),0)>Method!$B$88),"PASS",IF(AND(AF5>=Method!$B$7,AG5>=Method!$B$8),"BET","PASS")))} -> PASS | AI5: =IF(AH5<>"BET",0,ROUND(MIN(Method!$B$6,Method!$B$5*AL5)*100,1)) -> 0 | AJ5: =IF(OR(AH5<>"BET",Method!$B$55=TRUE()),0,IF(AI5*Method!$B$10/100<Method!$B$9,0,ROUND(AI5*Method!$B$10/100,0))) -> 0 | AK5: =IF(AB5="","",INDEX(V5:X5,1,AB5)) -> 0.46585091 | AL5: =IF(AH5<>"BET","",MAX(0,(AK5*AE5-1)/(AE5-1))) | AM5: =IF(AH5="BET",AF5+A5/1000000,"") | AN5: =IF(Matchday!N7="","",Matchday!N7) -> Y | AO5: =IF(Matchday!P7="","",Matchday!P7) -> 2.05 | AP5: =IF(Matchday!Q7="","",Matchday!Q7) -> 20 | AQ5: =IF(Matchday!R7="","",Matchday!R7) -> H | AR5: =IF(OR(AN5<>"Y",AQ5="",AV5=""),"",IF(AQ5="Void",0,IF(AQ5=AV5,ROUND(AP5*(AO5-1),2),-AP5))) -> 21 | AS5: =IF(AR5="","",SUM($AR$2:AR5)) -> 21.4 | AT5: =IFERROR(__xludf.DUMMYFUNCTION("IF(AB5="""",""Type the 3 odds on the Matchday tab"",IF(Method!$B$55=TRUE(),IF(Method!$B$81=TRUE(),IF(REGEXMATCH(LOWER(Method!$B$63),""circuit""),""🛑 PAUSED — circuit breaker upstream; wait for a clean live refresh."",IF(REGEXMATCH(LOWER(Method!$B$63),""p"&"ipeline""),""🛑 PAUSED — live pipeline warning; check Live!B11/Method!B62 before betting."",IF(REGEXMATCH(LOWER(Method!$B$63),""missing""),""🛑 PAUSED — feed timestamp missing; refresh feed before betting."",""🛑 PAUSED — feed stale > 25 min — check Live "&"tab; refresh feed before betting.""))),IF(Method!$B$51>=Method!$B$52,""🛑 PAUSED — drawdown ""&TEXT(Method!$B$51,""0.0%"")&"" ≥ ""&TEXT(Method!$B$52,""0.0%"")&"". Set Method!B54=Y to override."",""🛑 PAUSED — see Method!B62/B63/B81 for cause; do not overr"&"ide stale/circuit-breaker/pipeline pauses."")),IF(AH5=""BET"",IF(AJ5=0,""Edge found but stake rounds under £""&Method!$B$9&"" — skip"",IF(AND(AE5>=6,AG5>=0.15),""🟡 WAIT — long-shot review: odds ""&TEXT(AE5,""0.00"")&"" + edge ""&TEXT(AG5,""0.0%"")&"" — v"&"erify sharp-book + team news + stake comfort before Placed=Y"",""Value found: EV ""&TEXT(AF5,""0.0%"")&"", edge ""&TEXT(AG5,""0.0%""))),IF(OR(AF5>Method!$B$87,IFERROR(INDEX(BC5:BE5,1,AB5)/INDEX(S5:U5,1,AB5),0)>Method!$B$88),""🛑 Tail trap — auto-PASS · EV"&" ""&TEXT(AF5,""0.0%"")&"" (cap ""&TEXT(Method!$B$87,""0%"")&"") · model/market ""&TEXT(IFERROR(INDEX(BC5:BE5,1,AB5)/INDEX(S5:U5,1,AB5),0),""0.0"")&""× (cap ""&TEXT(Method!$B$88,""0.0"")&""×)"",IF(AF5<Method!$B$7,""Price too short — EV ""&TEXT(AF5,""0.0%"""&")&"" (need ""&TEXT(Method!$B$7,""0.0%"")&""+)"",""Model ≈ market — edge ""&TEXT(AG5,""0.0%"")&"" (need ""&TEXT(Method!$B$8,""0.0%"")&""+)"")))))"),"Price too short — EV 1.6% (need 2.5%+)") -> Price too short — EV 1.6% (need 2.5%+) | AU5: =IF(AN5<>"Y","",IF(AH5="· enter odds","⚠ type the 3 odds (1/X/2) to grade this bet",IF(OR(AV5="",AO5="",AP5=""),"⚠ log backed pick, odds & stake",IF(AZ5<>"BET","⚠ FUN BET — engine said pass · staked £"&AP5&" vs engine £"&BA5,IF(AV5<>IF(AY5="",AC5,AY5),"⚠ backed "&AV5&" but engine pick was "&IF(AY5="",AC5,AY5),IF(AP5>BA5,"⚠ stake over engine £"&BA5,IF(ABS(AO5-IFERROR(INDEX(L5:N5,1,MATCH(AV5,{"H","D","A"},0)),AE5))>0.02,"⚠ odds moved — re-check value","✓ engine bet"))))))) -> ⚠ FUN BET — engine said pass · staked £20 vs engine £0 | AV5: =IF(Matchday!O7="","",Matchday!O7) -> H | AW5: PASS | AX5: 0 | AY5: H | AZ5: =IF(AW5="",AH5,AW5) -> PASS | BA5: =IF(AX5<>"",AX5,IF(AH5<>"BET",0,IF(AI5*Method!$B$10/100<Method!$B$9,0,ROUND(AI5*Method!$B$10/100,0)))) -> 0 | BB5: -56.01 | BC5: 0.48292199 | BD5: 0.27080493 | BE5: 0.24627308 | BF5: Paraguay team-wide: -35 · United States team-wide: -21 | BG5: 30 | BH5: warm_dry_indoor | BI5: 0
A6: 5 | B6: 46186 | C6: B | D6: Qatar | E6: Switzerland | F6: Santa Clara | G6: 0.5 | H6: 0.83333333 | I6: 0.07585287 | J6: 0.19789443 | K6: 0.7262527 | L6: =IF(Matchday!E8="","",Matchday!E8) -> 14 | M6: =IF(Matchday!F8="","",Matchday!F8) -> 7.5 | N6: =IF(Matchday!G8="","",Matchday!G8) -> 1.2 | O6: =IF(L6="","",1/L6) -> 0.071428571 | P6: =IF(M6="","",1/M6) -> 0.13333333 | Q6: =IF(N6="","",1/N6) -> 0.83333333 | R6: =IF(COUNT(L6:N6)<3,"",O6+P6+Q6) -> 1.0380952 | S6: {=IF($R6="","",IF(Method!$B$56="proportional",O6/$R6,IF(Method!$B$56="power",IFERROR(INDEX(power_devig($L6,$M6,$N6),1,1),O6/$R6),IFERROR(INDEX(shin($L6,$M6,$N6),1,1),O6/$R6))))} -> 0.061439258 | T6: {=IF($R6="","",IF(Method!$B$56="proportional",P6/$R6,IF(Method!$B$56="power",IFERROR(INDEX(power_devig($L6,$M6,$N6),2,1),P6/$R6),IFERROR(INDEX(shin($L6,$M6,$N6),2,1),P6/$R6))))} -> 0.12247683 | U6: {=IF($R6="","",IF(Method!$B$56="proportional",Q6/$R6,IF(Method!$B$56="power",IFERROR(INDEX(power_devig($L6,$M6,$N6),3,1),Q6/$R6),IFERROR(INDEX(shin($L6,$M6,$N6),3,1),Q6/$R6))))} -> 0.81608391 | V6: =IF(S6="","",Method!$B$4*IF(BC6="",I6,BC6)+(1-Method!$B$4)*S6/($S6+$T6+$U6)) -> 0.066429991 | W6: =IF(T6="","",Method!$B$4*IF(BD6="",J6,BD6)+(1-Method!$B$4)*T6/($S6+$T6+$U6)) -> 0.15615122 | X6: =IF(U6="","",Method!$B$4*IF(BE6="",K6,BE6)+(1-Method!$B$4)*U6/($S6+$T6+$U6)) -> 0.77741879 | Y6: =IF(V6="","",V6*L6-1) -> -0.069980126 | Z6: =IF(W6="","",W6*M6-1) -> 0.17113412 | AA6: =IF(X6="","",X6*N6-1) -> -0.067097448 | AB6: =IF(Y6="","",MATCH(MAX(Y6:AA6),Y6:AA6,0)) -> 2 | AC6: =IF(AB6="","",CHOOSE(AB6,"H","D","A")) -> D | AD6: =IF(AB6="","",CHOOSE(AB6,"1 "&D6,"X Draw","2 "&E6)) -> X Draw | AE6: =IF(AB6="","",INDEX(L6:N6,1,AB6)) -> 7.5 | AF6: =IF(AB6="","",INDEX(Y6:AA6,1,AB6)) -> 0.17113412 | AG6: =IF(AB6="","",INDEX(V6:X6,1,AB6)-INDEX(S6:U6,1,AB6)) -> 0.033674381 | AH6: {=IF(AB6="","· enter odds",IF(OR(AF6>Method!$B$87,IFERROR(INDEX(BC6:BE6,1,AB6)/INDEX(S6:U6,1,AB6),0)>Method!$B$88),"PASS",IF(AND(AF6>=Method!$B$7,AG6>=Method!$B$8),"BET","PASS")))} -> BET | AI6: =IF(AH6<>"BET",0,ROUND(MIN(Method!$B$6,Method!$B$5*AL6)*100,1)) -> 0.7 | AJ6: =IF(OR(AH6<>"BET",Method!$B$55=TRUE()),0,IF(AI6*Method!$B$10/100<Method!$B$9,0,ROUND(AI6*Method!$B$10/100,0))) -> 7 | AK6: =IF(AB6="","",INDEX(V6:X6,1,AB6)) -> 0.15615122 | AL6: =IF(AH6<>"BET","",MAX(0,(AK6*AE6-1)/(AE6-1))) -> 0.026328325 | AM6: =IF(AH6="BET",AF6+A6/1000000,"") -> 0.17113912 | AN6: =IF(Matchday!N8="","",Matchday!N8) -> Y | AO6: =IF(Matchday!P8="","",Matchday!P8) -> 7.5 | AP6: =IF(Matchday!Q8="","",Matchday!Q8) -> 20 | AQ6: =IF(Matchday!R8="","",Matchday!R8) -> D | AR6: =IF(OR(AN6<>"Y",AQ6="",AV6=""),"",IF(AQ6="Void",0,IF(AQ6=AV6,ROUND(AP6*(AO6-1),2),-AP6))) -> -20 | AS6: =IF(AR6="","",SUM($AR$2:AR6)) -> 1.4 | AT6: =IFERROR(__xludf.DUMMYFUNCTION("IF(AB6="""",""Type the 3 odds on the Matchday tab"",IF(Method!$B$55=TRUE(),IF(Method!$B$81=TRUE(),IF(REGEXMATCH(LOWER(Method!$B$63),""circuit""),""🛑 PAUSED — circuit breaker upstream; wait for a clean live refresh."",IF(REGEXMATCH(LOWER(Method!$B$63),""p"&"ipeline""),""🛑 PAUSED — live pipeline warning; check Live!B11/Method!B62 before betting."",IF(REGEXMATCH(LOWER(Method!$B$63),""missing""),""🛑 PAUSED — feed timestamp missing; refresh feed before betting."",""🛑 PAUSED — feed stale > 25 min — check Live "&"tab; refresh feed before betting.""))),IF(Method!$B$51>=Method!$B$52,""🛑 PAUSED — drawdown ""&TEXT(Method!$B$51,""0.0%"")&"" ≥ ""&TEXT(Method!$B$52,""0.0%"")&"". Set Method!B54=Y to override."",""🛑 PAUSED — see Method!B62/B63/B81 for cause; do not overr"&"ide stale/circuit-breaker/pipeline pauses."")),IF(AH6=""BET"",IF(AJ6=0,""Edge found but stake rounds under £""&Method!$B$9&"" — skip"",IF(AND(AE6>=6,AG6>=0.15),""🟡 WAIT — long-shot review: odds ""&TEXT(AE6,""0.00"")&"" + edge ""&TEXT(AG6,""0.0%"")&"" — v"&"erify sharp-book + team news + stake comfort before Placed=Y"",""Value found: EV ""&TEXT(AF6,""0.0%"")&"", edge ""&TEXT(AG6,""0.0%""))),IF(OR(AF6>Method!$B$87,IFERROR(INDEX(BC6:BE6,1,AB6)/INDEX(S6:U6,1,AB6),0)>Method!$B$88),""🛑 Tail trap — auto-PASS · EV"&" ""&TEXT(AF6,""0.0%"")&"" (cap ""&TEXT(Method!$B$87,""0%"")&"") · model/market ""&TEXT(IFERROR(INDEX(BC6:BE6,1,AB6)/INDEX(S6:U6,1,AB6),0),""0.0"")&""× (cap ""&TEXT(Method!$B$88,""0.0"")&""×)"",IF(AF6<Method!$B$7,""Price too short — EV ""&TEXT(AF6,""0.0%"""&")&"" (need ""&TEXT(Method!$B$7,""0.0%"")&""+)"",""Model ≈ market — edge ""&TEXT(AG6,""0.0%"")&"" (need ""&TEXT(Method!$B$8,""0.0%"")&""+)"")))))"),"Value found: EV 17.1%, edge 3.4%") -> Value found: EV 17.1%, edge 3.4% | AU6: =IF(AN6<>"Y","",IF(AH6="· enter odds","⚠ type the 3 odds (1/X/2) to grade this bet",IF(OR(AV6="",AO6="",AP6=""),"⚠ log backed pick, odds & stake",IF(AZ6<>"BET","⚠ FUN BET — engine said pass · staked £"&AP6&" vs engine £"&BA6,IF(AV6<>IF(AY6="",AC6,AY6),"⚠ backed "&AV6&" but engine pick was "&IF(AY6="",AC6,AY6),IF(AP6>BA6,"⚠ stake over engine £"&BA6,IF(ABS(AO6-IFERROR(INDEX(L6:N6,1,MATCH(AV6,{"H","D","A"},0)),AE6))>0.02,"⚠ odds moved — re-check value","✓ engine bet"))))))) -> ⚠ FUN BET — engine said pass · staked £20 vs engine £0 | AV6: =IF(Matchday!O8="","",Matchday!O8) -> A | AW6: PASS | AX6: 0 | AY6: D | AZ6: =IF(AW6="",AH6,AW6) -> PASS | BA6: =IF(AX6<>"",AX6,IF(AH6<>"BET",0,IF(AI6*Method!$B$10/100<Method!$B$9,0,ROUND(AI6*Method!$B$10/100,0)))) -> 0 | BB6: -53.4 | BC6: 0.075698495 | BD6: 0.21868935 | BE6: 0.70561215 | BF6: Qatar team-wide: -35 · Switzerland team-wide: -18 | BG6: 8 | BH6: mild_dry | BI6: 0
